<?xml version="1.0" ?>
<robot name="hingecabinet_urdf">
    <link name="hingecabinet">
        <inertial>
            <origin xyz="0 0 0" rpy="0 0 0"/>
            <mass value="0"/>
            <inertia ixx="0" ixy="0" ixz="0" iyy="0" iyz="0" izz="0"/>
        </inertial>
    </link>

    <!-- cabinet -->
    <link name="hingecab">
		<inertial>
            <origin xyz="0 0 0" rpy="0 0 0"/>
			<mass value="154.62400"/>
			<inertia ixx="6.70037" ixy="0" ixz="0" iyy="10.30827" iyz="0" izz="12.88533"/>
		</inertial>
        <visual>
            <origin xyz="0 0 0" rpy="0 0 0"/>
            <geometry>
                <box size="0.08 0.6 0.4"/>
            </geometry>
            <material name="M_hinge_blue">
                <color rgba=".46 .5 .6 1"/>
            </material>
        </visual>
        <collision>
            <origin xyz="0 0 0" rpy="0 0 0"/>
            <geometry>
                <box size="0.08 0.6 0.4"/>
            </geometry>
        </collision>
        <visual>
            <origin xyz="0.38 0 0" rpy="0 0 0"/>
            <geometry>
                <box size="0.04 0.6 0.4"/>
            </geometry>
            <material name="M_hinge_blue">
                <color rgba=".46 .5 .6 1"/>
            </material>
        </visual>
        <collision>
            <origin xyz="0.38 0 0" rpy="0 0 0"/>
            <geometry>
                <box size="0.04 0.6 0.4"/>
            </geometry>
        </collision>
        <visual>
            <origin xyz="-0.38 0 0" rpy="0 0 0"/>
            <geometry>
                <box size="0.04 0.6 0.4"/>
            </geometry>
            <material name="M_hinge_blue">
                <color rgba=".46 .5 .6 1"/>
            </material>
        </visual>
        <collision>
            <origin xyz="-0.38 0 0" rpy="0 0 0"/>
            <geometry>
                <box size="0.04 0.6 0.4"/>
            </geometry>
        </collision>
        <visual>
            <origin xyz="-0.2 0 0.18" rpy="0 0 0"/>
            <geometry>
                <box size="0.32 0.6 0.04"/>
            </geometry>
            <material name="M_hinge_blue">
                <color rgba=".46 .5 .6 1"/>
            </material>
        </visual>
        <collision>
            <origin xyz="-0.2 0 0.18" rpy="0 0 0"/>
            <geometry>
                <box size="0.32 0.6 0.04"/>
            </geometry>
        </collision>
        <visual>
            <origin xyz="-0.2 0 -0.18" rpy="0 0 0"/>
            <geometry>
                <box size="0.32 0.6 0.04"/>
            </geometry>
            <material name="M_hinge_blue">
                <color rgba=".46 .5 .6 1"/>
            </material>
        </visual>
        <collision>
            <origin xyz="-0.2 0 -0.18" rpy="0 0 0"/>
            <geometry>
                <box size="0.32 0.6 0.04"/>
            </geometry>
        </collision>
        <visual>
            <origin xyz="0.2 0 -0.18" rpy="0 0 0"/>
            <geometry>
                <box size="0.32 0.6 0.04"/>
            </geometry>
            <material name="M_hinge_blue">
                <color rgba=".46 .5 .6 1"/>
            </material>
        </visual>
        <collision>
            <origin xyz="0.2 0 -0.18" rpy="0 0 0"/>
            <geometry>
                <box size="0.32 0.6 0.04"/>
            </geometry>
        </collision>
        <visual>
            <origin xyz="0.2 0 0.18" rpy="0 0 0"/>
            <geometry>
                <box size="0.32 0.6 0.04"/>
            </geometry>
            <material name="M_hinge_blue">
                <color rgba=".46 .5 .6 1"/>
            </material>
        </visual>
        <collision>
            <origin xyz="0.2 0 0.18" rpy="0 0 0"/>
            <geometry>
                <box size="0.32 0.6 0.04"/>
            </geometry>
        </collision>
        <visual>
            <origin xyz="-0.2 0.28 0" rpy="0 0 0"/>
            <geometry>
                <box size="0.32 0.04 0.32"/>
            </geometry>
            <material name="M_hinge_blue">
                <color rgba=".46 .5 .6 1"/>
            </material>
        </visual>
        <collision>
            <origin xyz="-0.2 0.28 0" rpy="0 0 0"/>
            <geometry>
                <box size="0.32 0.04 0.32"/>
            </geometry>
        </collision>
        <visual>
            <origin xyz="0.2 0.28 0" rpy="0 0 0"/>
            <geometry>
                <box size="0.32 0.04 0.32"/>
            </geometry>
            <material name="M_hinge_blue">
                <color rgba=".46 .5 .6 1"/>
            </material>
        </visual>
        <collision>
            <origin xyz="0.2 0.28 0" rpy="0 0 0"/>
            <geometry>
                <box size="0.32 0.04 0.32"/>
            </geometry>
        </collision>
    </link>

    <!-- link for left door joint -->
    <link name="hingecabinet_link_1">
        <inertial>
            <origin xyz="0 0 0" rpy="0 0 0"/>
            <mass value="0"/>
            <inertia ixx="0" ixy="0" ixz="0" iyy="0" iyz="0" izz="0"/>
        </inertial>
    </link>

    <!-- left door -->
    <link name="hingeleftdoor_1">
		<inertial>
            <origin xyz="0 0 0" rpy="0 0 0"/>
			<mass value="19.98200"/>
			<inertia ixx="0.31176" ixy="0" ixz="0" iyy="0.51453" iyz="0" izz="0.29344"/>
		</inertial>
        <visual>
            <origin xyz="0.302 -0.128 0" rpy="0 0 0"/>
            <geometry>
                <cylinder radius="0.022" length="0.32"/>
            </geometry>
            <material name="T_hinge_metal">
                <texture filename="../textures/metal1.png"/>
            </material>
        </visual>
        <collision>
            <origin xyz="0.302 -0.128 0" rpy="0 0 0"/>
            <geometry>
                <cylinder radius="0.022" length="0.32"/>
            </geometry>
        </collision>
        <visual>
            <origin xyz="0.302 -0.061 0.114" rpy="1.57 0 0"/>
            <geometry>
                <cylinder radius="0.019" length="0.106"/>
            </geometry>
            <material name="T_hinge_metal">
                <texture filename="../textures/metal1.png"/>
            </material>
        </visual>
        <collision>
            <origin xyz="0.302 -0.061 0.114" rpy="1.57 0 0"/>
            <geometry>
                <cylinder radius="0.019" length="0.106"/>
            </geometry>
        </collision>
        <visual>
            <origin xyz="0.302 -0.061 -0.114" rpy="1.57 0 0"/>
            <geometry>
                <cylinder radius="0.019" length="0.106"/>
            </geometry>
            <material name="T_hinge_metal">
                <texture filename="../textures/metal1.png"/>
            </material>
        </visual>
        <collision>
            <origin xyz="0.302 -0.061 -0.114" rpy="1.57 0 0"/>
            <geometry>
                <cylinder radius="0.019" length="0.106"/>
            </geometry>
        </collision>
    </link>
    <link name="hingeleftdoor_2">
		<inertial>
            <origin xyz="0 0 0" rpy="0 0 0"/>
			<mass value="19.98200"/>
			<inertia ixx="0.31176" ixy="0" ixz="0" iyy="0.51453" iyz="0" izz="0.29344"/>
		</inertial>
        <visual>
            <origin xyz="0.184 -.015 0" rpy="0 0 0"/>
            <geometry>
                <box size="0.386 0.06 0.4"/>
            </geometry>
            <material name="M_hinge_blue">
                <color rgba=".46 .5 .6 1"/>
            </material>
        </visual>
        <collision>
            <origin xyz="0.184 -.015 0" rpy="0 0 0"/>
            <geometry>
                <box size="0.386 0.06 0.4"/>
            </geometry>
        </collision>
    </link>

    <!-- link for right door joint -->
    <link name="hingecabinet_link_2">
        <inertial>
            <origin xyz="0 0 0" rpy="0 0 0"/>
            <mass value="0"/>
            <inertia ixx="0" ixy="0" ixz="0" iyy="0" iyz="0" izz="0"/>
        </inertial>
    </link>

    <!-- right door -->
    <link name="hingerightdoor_1">
		<inertial>
            <origin xyz="0 0 0" rpy="0 0 0"/>
			<mass value="19.98200"/>
			<inertia ixx="0.31176" ixy="0" ixz="0" iyy="0.51453" iyz="0" izz="0.29344"/>
		</inertial>
        <visual>
            <origin xyz="-0.302 -0.128 0" rpy="0 0 0"/>
            <geometry>
                <cylinder radius="0.022" length="0.32"/>
            </geometry>
            <material name="T_hinge_metal">
                <texture filename="../textures/metal1.png"/>
            </material>
        </visual>
        <collision>
            <origin xyz="-0.302 -0.128 0" rpy="0 0 0"/>
            <geometry>
                <cylinder radius="0.022" length="0.32"/>
            </geometry>
        </collision>
        <visual>
            <origin xyz="-0.302 -0.061 -0.114" rpy="1.57 0 0"/>
            <geometry>
                <cylinder radius="0.019" length="0.106"/>
            </geometry>
            <material name="T_hinge_metal">
                <texture filename="../textures/metal1.png"/>
            </material>
        </visual>
        <collision>
            <origin xyz="-0.302 -0.061 -0.114" rpy="1.57 0 0"/>
            <geometry>
                <cylinder radius="0.019" length="0.106"/>
            </geometry>
        </collision>
        <visual>
            <origin xyz="-0.302 -0.061 0.114" rpy="1.57 0 0"/>
            <geometry>
                <cylinder radius="0.019" length="0.106"/>
            </geometry>
            <material name="T_hinge_metal">
                <texture filename="../textures/metal1.png"/>
            </material>
        </visual>
        <collision>
            <origin xyz="-0.302 -0.061 0.114" rpy="1.57 0 0"/>
            <geometry>
                <cylinder radius="0.019" length="0.106"/>
            </geometry>
        </collision>
    </link>
    <link name="hingerightdoor_2">
		<inertial>
            <origin xyz="0 0 0" rpy="0 0 0"/>
			<mass value="19.98200"/>
			<inertia ixx="0.31176" ixy="0" ixz="0" iyy="0.51453" iyz="0" izz="0.29344"/>
		</inertial>
        <visual>
            <origin xyz="-0.185 -.015 0" rpy="0 0 0"/>
            <geometry>
                <box size="0.386 0.06 0.4"/>
            </geometry>
            <material name="M_hinge_blue">
                <color rgba=".46 .5 .6 1"/>
            </material>
        </visual>
        <collision>
            <origin xyz="-0.185 -.015 0" rpy="0 0 0"/>
            <geometry>
                <box size="0.386 0.06 0.4"/>
            </geometry>
        </collision>
    </link>

    <!-- hingecabinet joints -->
    <joint name="hingecabinet_hingecab" type="fixed">
        <origin xyz="0 0 0" rpy="0 0 0"/>
        <parent link="hingecabinet"/>
        <child link="hingecab"/>
    </joint>
	<joint name="left_hinge_cabinet" type="revolute">
		<origin xyz="-0.38 -0.32 0" rpy="0 0 0"/>
        <parent link="hingecab"/>
		<child link="hingecabinet_link_1"/>
        <axis xyz="0 0 1"/>
		<dynamics damping="1.0" friction="0.0001"/>
        <limit lower="-1.57" upper="0" effort="0" velocity="0"/>
	</joint>
    <joint name="hingecabinet_link_1_hingeleftdoor_1" type="fixed">
        <origin xyz="0 0 0" rpy="0 0 0"/>
		<parent link="hingecabinet_link_1"/>
		<child link="hingeleftdoor_1"/>
	</joint>
    <joint name="hingecabinet_link_1_hingeleftdoor_2" type="fixed">
        <origin xyz="0 0 0" rpy="0 0 0"/>
		<parent link="hingecabinet_link_1"/>
		<child link="hingeleftdoor_2"/>
	</joint>
	<joint name="right_hinge_cabinet" type="revolute">
		<origin xyz="0.38 -0.32 0" rpy="0 0 0"/>
        <parent link="hingecab"/>
		<child link="hingecabinet_link_2"/>
        <axis xyz="0 0 1"/>
		<dynamics damping="1.0" friction="0.0001"/>
		<limit lower="0" upper="1.57" effort="0" velocity="0"/>
	</joint>
    <joint name="hingecabinet_link_2_hingerightdoor_1" type="fixed">
        <origin xyz="0 0 0" rpy="0 0 0"/>
		<parent link="hingecabinet_link_2"/>
		<child link="hingerightdoor_1"/>
	</joint>
    <joint name="hingecabinet_link_2_hingerightdoor_2" type="fixed">
        <origin xyz="0 0 0" rpy="0 0 0"/>
		<parent link="hingecabinet_link_2"/>
		<child link="hingerightdoor_2"/>
	</joint>
</robot>
