<?xml version="0.0" ?>
<robot name="franka_kitchen">
	<link name="desk">
		<inertial>
			<origin rpy="0.00000 -0.00000 0.00000" xyz="0.00000 0.00000 0.00000"/>
			<mass value="0.00000"/>
			<inertia ixx="0.00000" ixy="0" ixz="0" iyy="0.00000" iyz="0" izz="0.00000"/>
		</inertial>
	</link>
	<link name="counters1">
		<inertial>
			<origin rpy="0.00000 -0.00000 0.00000" xyz="0.00000 0.00000 0.00000"/>
			<mass value="0.00000"/>
			<inertia ixx="0.00000" ixy="0" ixz="0" iyy="0.00000" iyz="0" izz="0.00000"/>
		</inertial>
	</link>
	<link name="counters">
		<inertial>
			<origin rpy="0.00000 -0.00000 0.00000" xyz="0.00000 0.00000 0.00000"/>
			<mass value="4442.39179"/>
			<inertia ixx="3571.10731" ixy="0" ixz="0" iyy="4266.05624" iyz="0" izz="4330.17486"/>
		</inertial>
		<collision>
			<origin rpy="0.00000 -0.00000 0.00000" xyz="0.00000 0.00000 0.00000"/>
			<geometry>
				<mesh filename="unknown_file" scale="1.00000 1.00000 1.00000"/>
			</geometry>
		</collision>
		<collision>
			<origin rpy="0.00000 -0.00000 0.00000" xyz="0.00000 0.00000 0.00000"/>
			<geometry>
				<mesh filename="unknown_file" scale="1.00000 1.00000 1.00000"/>
			</geometry>
		</collision>
		<collision>
			<origin rpy="0.00000 -0.00000 0.00000" xyz="-0.85500 -0.50800 1.57000"/>
			<geometry>
				<box size="0.92600 2.16000 0.06000"/>
			</geometry>
		</collision>
		<collision>
			<origin rpy="0.00000 -0.00000 0.00000" xyz="0.90400 -0.17200 1.51100"/>
			<geometry>
				<mesh filename="unknown_file" scale="1.00000 1.00000 1.00000"/>
			</geometry>
		</collision>
		<collision>
			<origin rpy="0.00000 -0.00000 0.00000" xyz="0.90000 0.08500 1.83000"/>
			<geometry>
				<cylinder length="0.10000" radius="0.03500"/>
			</geometry>
		</collision>
		<collision>
			<origin rpy="0.00000 -0.00000 0.00000" xyz="0.90000 0.08500 1.92000"/>
			<geometry>
				<capsule length="0.16000" radius="0.02500"/>
			</geometry>
		</collision>
		<collision>
			<origin rpy="0.00000 -0.00000 0.00000" xyz="0.90000 0.20000 2.00000"/>
			<geometry>
				<capsule length="0.22000" radius="0.02500"/>
			</geometry>
		</collision>
		<collision>
			<origin rpy="0.00000 -0.00000 0.00000" xyz="0.90000 0.31700 1.80000"/>
			<geometry>
				<capsule length="0.40000" radius="0.02500"/>
			</geometry>
		</collision>
		<collision>
			<origin rpy="0.00000 -0.00000 0.00000" xyz="0.90000 0.31700 1.67000"/>
			<geometry>
				<cylinder length="0.14000" radius="0.03200"/>
			</geometry>
		</collision>
		<collision>
			<origin rpy="0.00000 -0.00000 0.00000" xyz="0.94700 0.31800 1.68000"/>
			<geometry>
				<cylinder length="0.06000" radius="0.02900"/>
			</geometry>
		</collision>
		<collision>
			<origin rpy="0.00000 -0.00000 0.00000" xyz="0.99000 0.31800 1.68000"/>
			<geometry>
				<cylinder length="0.02600" radius="0.03500"/>
			</geometry>
		</collision>
		<collision>
			<origin rpy="0.00000 -0.00000 0.00000" xyz="0.99000 0.26000 1.68000"/>
			<geometry>
				<capsule length="0.06000" radius="0.01000"/>
			</geometry>
		</collision>
		<collision>
			<origin rpy="0.00000 -0.00000 0.00000" xyz="0.90900 -0.69500 1.39000"/>
			<geometry>
				<cylinder length="0.56000" radius="0.02200"/>
			</geometry>
		</collision>
		<collision>
			<origin rpy="0.00000 -0.00000 0.00000" xyz="0.71000 -0.66500 1.39000"/>
			<geometry>
				<cylinder length="0.06000" radius="0.01800"/>
			</geometry>
		</collision>
		<collision>
			<origin rpy="0.00000 -0.00000 0.00000" xyz="1.10800 -0.66500 1.39000"/>
			<geometry>
				<cylinder length="0.06000" radius="0.01800"/>
			</geometry>
		</collision>
		<collision>
			<origin rpy="0.00000 -0.00000 0.00000" xyz="0.90900 -0.69500 1.14000"/>
			<geometry>
				<cylinder length="0.56000" radius="0.02200"/>
			</geometry>
		</collision>
		<collision>
			<origin rpy="0.00000 -0.00000 0.00000" xyz="0.71000 -0.66500 1.14000"/>
			<geometry>
				<cylinder length="0.06000" radius="0.01800"/>
			</geometry>
		</collision>
		<collision>
			<origin rpy="0.00000 -0.00000 0.00000" xyz="1.10800 -0.66500 1.14000"/>
			<geometry>
				<cylinder length="0.06000" radius="0.01800"/>
			</geometry>
		</collision>
		<collision>
			<origin rpy="0.00000 -0.00000 0.00000" xyz="0.90900 -0.69500 1.39000"/>
			<geometry>
				<cylinder length="0.56000" radius="0.02200"/>
			</geometry>
		</collision>
		<collision>
			<origin rpy="0.00000 -0.00000 0.00000" xyz="0.71000 -0.66500 1.39000"/>
			<geometry>
				<cylinder length="0.06000" radius="0.01800"/>
			</geometry>
		</collision>
		<collision>
			<origin rpy="0.00000 -0.00000 0.00000" xyz="1.10800 -0.66500 1.39000"/>
			<geometry>
				<cylinder length="0.06000" radius="0.01800"/>
			</geometry>
		</collision>
		<collision>
			<origin rpy="0.00000 -0.00000 0.00000" xyz="0.90900 -0.69500 1.14000"/>
			<geometry>
				<cylinder length="0.56000" radius="0.02200"/>
			</geometry>
		</collision>
		<collision>
			<origin rpy="0.00000 -0.00000 0.00000" xyz="0.71000 -0.66500 1.14000"/>
			<geometry>
				<cylinder length="0.06000" radius="0.01800"/>
			</geometry>
		</collision>
		<collision>
			<origin rpy="0.00000 -0.00000 0.00000" xyz="1.10800 -0.66500 1.14000"/>
			<geometry>
				<cylinder length="0.06000" radius="0.01800"/>
			</geometry>
		</collision>
		<collision>
			<origin rpy="0.00000 -0.00000 0.00000" xyz="-0.86000 -0.50000 0.78000"/>
			<geometry>
				<box size="0.92000 2.14000 1.55400"/>
			</geometry>
		</collision>
		<collision>
			<origin rpy="0.00000 -0.00000 0.00000" xyz="0.90700 -0.04500 0.71000"/>
			<geometry>
				<box size="0.60800 1.21200 1.42000"/>
			</geometry>
		</collision>
		<collision>
			<origin rpy="0.00000 -0.00000 0.00000" xyz="-0.85500 -0.50800 1.57000"/>
			<geometry>
				<box size="0.92600 2.16000 0.06000"/>
			</geometry>
		</collision>
		<collision>
			<origin rpy="0.00000 -0.00000 0.00000" xyz="1.15900 -0.04500 1.57000"/>
			<geometry>
				<box size="0.10200 1.22200 0.06000"/>
			</geometry>
		</collision>
		<collision>
			<origin rpy="0.00000 -0.00000 0.00000" xyz="0.64900 -0.04500 1.57000"/>
			<geometry>
				<box size="0.10200 1.22200 0.06000"/>
			</geometry>
		</collision>
		<collision>
			<origin rpy="0.00000 -0.00000 0.00000" xyz="0.90400 0.40000 1.57000"/>
			<geometry>
				<box size="0.40800 0.33000 0.06000"/>
			</geometry>
		</collision>
		<collision>
			<origin rpy="0.00000 -0.00000 0.00000" xyz="0.90400 -0.61700 1.57000"/>
			<geometry>
				<box size="0.40800 0.07800 0.06000"/>
			</geometry>
		</collision>
		<collision>
			<origin rpy="0.00000 -0.00000 0.00000" xyz="1.15800 -0.04000 1.47000"/>
			<geometry>
				<box size="0.10000 1.22000 0.15200"/>
			</geometry>
		</collision>
		<collision>
			<origin rpy="0.00000 -0.00000 0.00000" xyz="0.65200 -0.04000 1.47000"/>
			<geometry>
				<box size="0.10000 1.22000 0.15200"/>
			</geometry>
		</collision>
		<collision>
			<origin rpy="0.00000 -0.00000 0.00000" xyz="0.90400 0.40100 1.47000"/>
			<geometry>
				<box size="0.40800 0.33200 0.15200"/>
			</geometry>
		</collision>
		<collision>
			<origin rpy="0.00000 -0.00000 0.00000" xyz="0.90400 -0.61100 1.47000"/>
			<geometry>
				<box size="0.41200 0.06800 0.15200"/>
			</geometry>
		</collision>
		<collision>
			<origin rpy="0.00000 -0.00000 0.00000" xyz="0.90000 0.08500 1.83000"/>
			<geometry>
				<cylinder length="0.10000" radius="0.03500"/>
			</geometry>
		</collision>
		<collision>
			<origin rpy="0.00000 -0.00000 0.00000" xyz="0.90000 0.08500 1.92000"/>
			<geometry>
				<capsule length="0.16000" radius="0.02500"/>
			</geometry>
		</collision>
		<collision>
			<origin rpy="0.00000 -0.00000 0.00000" xyz="0.90000 0.20000 2.00000"/>
			<geometry>
				<capsule length="0.22000" radius="0.02500"/>
			</geometry>
		</collision>
		<collision>
			<origin rpy="0.00000 -0.00000 0.00000" xyz="0.90000 0.31700 1.80000"/>
			<geometry>
				<capsule length="0.40000" radius="0.02500"/>
			</geometry>
		</collision>
		<collision>
			<origin rpy="0.00000 -0.00000 0.00000" xyz="0.90000 0.31700 1.67000"/>
			<geometry>
				<cylinder length="0.14000" radius="0.03200"/>
			</geometry>
		</collision>
		<collision>
			<origin rpy="0.00000 -0.00000 0.00000" xyz="0.94700 0.31800 1.68000"/>
			<geometry>
				<cylinder length="0.06000" radius="0.02900"/>
			</geometry>
		</collision>
		<collision>
			<origin rpy="0.00000 -0.00000 0.00000" xyz="0.99000 0.31800 1.68000"/>
			<geometry>
				<cylinder length="0.02600" radius="0.03500"/>
			</geometry>
		</collision>
		<collision>
			<origin rpy="0.00000 -0.00000 0.00000" xyz="0.99000 0.26000 1.68000"/>
			<geometry>
				<capsule length="0.06000" radius="0.01000"/>
			</geometry>
		</collision>
	</link>
	<link name="oven">
		<inertial>
			<origin rpy="0.00000 -0.00000 0.00000" xyz="0.00000 0.00000 0.00000"/>
			<mass value="0.00000"/>
			<inertia ixx="0.00000" ixy="0" ixz="0" iyy="0.00000" iyz="0" izz="0.00000"/>
		</inertial>
	</link>
	<link name="ovenroot">
		<inertial>
			<origin rpy="0.00000 -0.00000 0.00000" xyz="0.00000 0.00000 0.00000"/>
			<mass value="3966.27050"/>
			<inertia ixx="1508.10986" ixy="0" ixz="0" iyy="1294.96774" iyz="0" izz="979.85454"/>
		</inertial>
		<collision>
			<origin rpy="0.00000 -0.00000 0.00000" xyz="-0.24000 -0.11900 0.62900"/>
			<geometry>
				<mesh filename="unknown_file" scale="1.00000 1.00000 1.00000"/>
			</geometry>
		</collision>
		<collision>
			<origin rpy="0.00000 -0.00000 0.00000" xyz="-0.23700 0.32200 0.62900"/>
			<geometry>
				<mesh filename="unknown_file" scale="1.00000 1.00000 1.00000"/>
			</geometry>
		</collision>
		<collision>
			<origin rpy="0.00000 -0.00000 0.00000" xyz="0.20400 0.32200 0.62900"/>
			<geometry>
				<mesh filename="unknown_file" scale="1.00000 1.00000 1.00000"/>
			</geometry>
		</collision>
		<collision>
			<origin rpy="0.00000 -0.00000 0.00000" xyz="0.20600 -0.11900 0.62900"/>
			<geometry>
				<mesh filename="unknown_file" scale="1.00000 1.00000 1.00000"/>
			</geometry>
		</collision>
		<collision>
			<origin rpy="0.00000 -0.00000 0.00000" xyz="-0.21500 -0.36000 -0.68200"/>
			<geometry>
				<cylinder length="0.06000" radius="0.01800"/>
			</geometry>
		</collision>
		<collision>
			<origin rpy="0.00000 -0.00000 0.00000" xyz="0.18400 -0.36000 -0.68200"/>
			<geometry>
				<cylinder length="0.06000" radius="0.01800"/>
			</geometry>
		</collision>
		<collision>
			<origin rpy="0.00000 -0.00000 0.00000" xyz="-0.01500 -0.39000 -0.68200"/>
			<geometry>
				<cylinder length="0.56000" radius="0.02200"/>
			</geometry>
		</collision>
		<collision>
			<origin rpy="0.00000 -0.00000 0.00000" xyz="-0.21500 -0.36000 0.25400"/>
			<geometry>
				<cylinder length="0.06000" radius="0.01800"/>
			</geometry>
		</collision>
		<collision>
			<origin rpy="0.00000 -0.00000 0.00000" xyz="0.18400 -0.36000 0.25400"/>
			<geometry>
				<cylinder length="0.06000" radius="0.01800"/>
			</geometry>
		</collision>
		<collision>
			<origin rpy="0.00000 -0.00000 0.00000" xyz="-0.01500 -0.39000 0.25400"/>
			<geometry>
				<cylinder length="0.56000" radius="0.02200"/>
			</geometry>
		</collision>
		<collision>
			<origin rpy="0.00000 -0.00000 0.00000" xyz="-0.01700 0.27500 0.60700"/>
			<geometry>
				<mesh filename="unknown_file" scale="1.00000 1.00000 1.00000"/>
			</geometry>
		</collision>
		<collision>
			<origin rpy="0.00000 -0.00000 0.00000" xyz="0.97930 0.29210 -1.18770"/>
			<geometry>
				<mesh filename="unknown_file" scale="1.00000 1.00000 1.00000"/>
			</geometry>
		</collision>
		<collision>
			<origin rpy="0.00000 -0.00000 0.00000" xyz="-0.01100 -0.32700 -0.05000"/>
			<geometry>
				<box size="0.70000 0.03200 0.44000"/>
			</geometry>
		</collision>
		<collision>
			<origin rpy="0.00000 -0.00000 0.00000" xyz="0.20300 0.32300 0.61900"/>
			<geometry>
				<mesh filename="unknown_file" scale="1.00000 1.00000 1.00000"/>
			</geometry>
		</collision>
		<collision>
			<origin rpy="0.00000 -0.00000 0.00000" xyz="-0.24000 -0.12000 0.61900"/>
			<geometry>
				<mesh filename="unknown_file" scale="1.00000 1.00000 1.00000"/>
			</geometry>
		</collision>
		<collision>
			<origin rpy="0.00000 -0.00000 0.00000" xyz="-0.23700 0.32300 0.61900"/>
			<geometry>
				<mesh filename="unknown_file" scale="1.00000 1.00000 1.00000"/>
			</geometry>
		</collision>
		<collision>
			<origin rpy="0.00000 -0.00000 0.00000" xyz="0.20700 -0.12000 0.61900"/>
			<geometry>
				<mesh filename="unknown_file" scale="1.00000 1.00000 1.00000"/>
			</geometry>
		</collision>
		<collision>
			<origin rpy="0.00000 -0.00000 0.00000" xyz="-0.01700 -0.32600 0.45500"/>
			<geometry>
				<box size="1.00000 0.03200 0.24000"/>
			</geometry>
		</collision>
		<collision>
			<origin rpy="0.00000 -0.00000 0.00000" xyz="-0.01700 -0.32600 -0.79500"/>
			<geometry>
				<box size="1.00000 0.03200 0.37000"/>
			</geometry>
		</collision>
		<collision>
			<origin rpy="0.00000 -0.00000 0.00000" xyz="-0.01700 -0.32600 -0.14000"/>
			<geometry>
				<box size="1.00000 0.03200 0.93000"/>
			</geometry>
		</collision>
		<collision>
			<origin rpy="0.00000 -0.00000 0.00000" xyz="-0.01700 0.29500 -0.20000"/>
			<geometry>
				<box size="1.00000 1.20400 1.56000"/>
			</geometry>
		</collision>
		<collision>
			<origin rpy="0.00000 -0.00000 0.00000" xyz="-0.01700 0.28000 -0.17500"/>
			<geometry>
				<box size="1.00000 1.25000 1.62000"/>
			</geometry>
		</collision>
		<collision>
			<origin rpy="0.00000 -0.00000 0.00000" xyz="-0.21500 -0.36000 -0.68200"/>
			<geometry>
				<cylinder length="0.06000" radius="0.01800"/>
			</geometry>
		</collision>
		<collision>
			<origin rpy="0.00000 -0.00000 0.00000" xyz="0.18400 -0.36000 -0.68200"/>
			<geometry>
				<cylinder length="0.06000" radius="0.01800"/>
			</geometry>
		</collision>
		<collision>
			<origin rpy="0.00000 -0.00000 0.00000" xyz="-0.01500 -0.39000 -0.68200"/>
			<geometry>
				<cylinder length="0.56000" radius="0.02200"/>
			</geometry>
		</collision>
		<collision>
			<origin rpy="0.00000 -0.00000 0.00000" xyz="-0.21500 -0.36000 0.25400"/>
			<geometry>
				<cylinder length="0.06000" radius="0.01800"/>
			</geometry>
		</collision>
		<collision>
			<origin rpy="0.00000 -0.00000 0.00000" xyz="0.18400 -0.36000 0.25400"/>
			<geometry>
				<cylinder length="0.06000" radius="0.01800"/>
			</geometry>
		</collision>
		<collision>
			<origin rpy="0.00000 -0.00000 0.00000" xyz="-0.01500 -0.39000 0.25400"/>
			<geometry>
				<cylinder length="0.56000" radius="0.02200"/>
			</geometry>
		</collision>
	</link>
	<link name="link0_6">
		<inertial>
			<origin rpy="0.00000 -0.00000 0.00000" xyz="0.00000 0.00000 0.00000"/>
			<mass value="0.00000"/>
			<inertia ixx="0.00000" ixy="0" ixz="0" iyy="0.00000" iyz="0" izz="0.00000"/>
		</inertial>
	</link>
	<link name="knob 1">
		<inertial>
			<origin rpy="0.00000 -0.00000 0.00000" xyz="0.00000 0.00000 0.00000"/>
			<mass value="0.46703"/>
			<inertia ixx="0.00059" ixy="0" ixz="0" iyy="0.00049" iyz="0" izz="0.00088"/>
		</inertial>
		<collision>
			<origin rpy="0.00000 -0.00000 0.00000" xyz="0.00000 0.00000 0.03800"/>
			<geometry>
				<box size="0.02800 0.09600 0.03600"/>
			</geometry>
		</collision>
		<collision>
			<origin rpy="0.00000 -0.00000 0.00000" xyz="0.00000 0.00000 0.01300"/>
			<geometry>
				<cylinder length="0.01600" radius="0.05000"/>
			</geometry>
		</collision>
		<collision>
			<origin rpy="0.00000 -0.00000 0.00000" xyz="0.00000 0.04800 0.03700"/>
			<geometry>
				<cylinder length="0.03600" radius="0.01400"/>
			</geometry>
		</collision>
		<collision>
			<origin rpy="0.00000 -0.00000 0.00000" xyz="0.00000 0.00000 0.03800"/>
			<geometry>
				<box size="0.02800 0.09600 0.03600"/>
			</geometry>
		</collision>
		<collision>
			<origin rpy="0.00000 -0.00000 0.00000" xyz="0.00000 0.00000 0.01300"/>
			<geometry>
				<cylinder length="0.01600" radius="0.05000"/>
			</geometry>
		</collision>
	</link>
	<link name="link0_8">
		<inertial>
			<origin rpy="0.00000 -0.00000 0.00000" xyz="0.00000 0.00000 0.00000"/>
			<mass value="0.00000"/>
			<inertia ixx="0.00000" ixy="0" ixz="0" iyy="0.00000" iyz="0" izz="0.00000"/>
		</inertial>
	</link>
	<link name="Burner 1">
		<inertial>
			<origin rpy="0.00000 -0.00000 0.00000" xyz="0.00000 0.00000 0.00000"/>
			<mass value="0.01000"/>
			<inertia ixx="0.00003" ixy="0" ixz="0" iyy="0.00003" iyz="0" izz="0.00005"/>
		</inertial>
		<collision>
			<origin rpy="0.00000 -0.00000 0.00000" xyz="0.00000 0.00000 0.00000"/>
			<geometry>
				<cylinder length="0.02000" radius="0.10000"/>
			</geometry>
		</collision>
	</link>
	<link name="link0_10">
		<inertial>
			<origin rpy="0.00000 -0.00000 0.00000" xyz="0.00000 0.00000 0.00000"/>
			<mass value="0.00000"/>
			<inertia ixx="0.00000" ixy="0" ixz="0" iyy="0.00000" iyz="0" izz="0.00000"/>
		</inertial>
	</link>
	<link name="knob 2">
		<inertial>
			<origin rpy="0.00000 -0.00000 0.00000" xyz="0.00000 0.00000 0.00000"/>
			<mass value="0.46703"/>
			<inertia ixx="0.00059" ixy="0" ixz="0" iyy="0.00049" iyz="0" izz="0.00088"/>
		</inertial>
		<collision>
			<origin rpy="0.00000 -0.00000 0.00000" xyz="0.00000 0.00000 0.03800"/>
			<geometry>
				<box size="0.02800 0.09600 0.03600"/>
			</geometry>
		</collision>
		<collision>
			<origin rpy="0.00000 -0.00000 0.00000" xyz="0.00000 0.00000 0.01300"/>
			<geometry>
				<cylinder length="0.01600" radius="0.05000"/>
			</geometry>
		</collision>
		<collision>
			<origin rpy="0.00000 -0.00000 0.00000" xyz="0.00000 0.04800 0.03700"/>
			<geometry>
				<cylinder length="0.03600" radius="0.01400"/>
			</geometry>
		</collision>
		<collision>
			<origin rpy="0.00000 -0.00000 0.00000" xyz="0.00000 0.00000 0.03800"/>
			<geometry>
				<box size="0.02800 0.09600 0.03600"/>
			</geometry>
		</collision>
		<collision>
			<origin rpy="0.00000 -0.00000 0.00000" xyz="0.00000 0.00000 0.01300"/>
			<geometry>
				<cylinder length="0.01600" radius="0.05000"/>
			</geometry>
		</collision>
	</link>
	<link name="link0_12">
		<inertial>
			<origin rpy="0.00000 -0.00000 0.00000" xyz="0.00000 0.00000 0.00000"/>
			<mass value="0.00000"/>
			<inertia ixx="0.00000" ixy="0" ixz="0" iyy="0.00000" iyz="0" izz="0.00000"/>
		</inertial>
	</link>
	<link name="Burner 2">
		<inertial>
			<origin rpy="0.00000 -0.00000 0.00000" xyz="0.00000 0.00000 0.00000"/>
			<mass value="0.01000"/>
			<inertia ixx="0.00003" ixy="0" ixz="0" iyy="0.00003" iyz="0" izz="0.00005"/>
		</inertial>
		<collision>
			<origin rpy="0.00000 -0.00000 0.00000" xyz="0.00000 0.00000 0.00000"/>
			<geometry>
				<cylinder length="0.02000" radius="0.10000"/>
			</geometry>
		</collision>
	</link>
	<link name="link0_14">
		<inertial>
			<origin rpy="0.00000 -0.00000 0.00000" xyz="0.00000 0.00000 0.00000"/>
			<mass value="0.00000"/>
			<inertia ixx="0.00000" ixy="0" ixz="0" iyy="0.00000" iyz="0" izz="0.00000"/>
		</inertial>
	</link>
	<link name="knob 3">
		<inertial>
			<origin rpy="0.00000 -0.00000 0.00000" xyz="0.00000 0.00000 0.00000"/>
			<mass value="0.46703"/>
			<inertia ixx="0.00059" ixy="0" ixz="0" iyy="0.00049" iyz="0" izz="0.00088"/>
		</inertial>
		<collision>
			<origin rpy="0.00000 -0.00000 0.00000" xyz="0.00000 0.00000 0.03800"/>
			<geometry>
				<box size="0.02800 0.09600 0.03600"/>
			</geometry>
		</collision>
		<collision>
			<origin rpy="0.00000 -0.00000 0.00000" xyz="0.00000 0.00000 0.01300"/>
			<geometry>
				<cylinder length="0.01600" radius="0.05000"/>
			</geometry>
		</collision>
		<collision>
			<origin rpy="0.00000 -0.00000 0.00000" xyz="0.00000 0.04800 0.03700"/>
			<geometry>
				<cylinder length="0.03600" radius="0.01400"/>
			</geometry>
		</collision>
		<collision>
			<origin rpy="0.00000 -0.00000 0.00000" xyz="0.00000 0.00000 0.03800"/>
			<geometry>
				<box size="0.02800 0.09600 0.03600"/>
			</geometry>
		</collision>
		<collision>
			<origin rpy="0.00000 -0.00000 0.00000" xyz="0.00000 0.00000 0.01300"/>
			<geometry>
				<cylinder length="0.01600" radius="0.05000"/>
			</geometry>
		</collision>
	</link>
	<link name="link0_16">
		<inertial>
			<origin rpy="0.00000 -0.00000 0.00000" xyz="0.00000 0.00000 0.00000"/>
			<mass value="0.00000"/>
			<inertia ixx="0.00000" ixy="0" ixz="0" iyy="0.00000" iyz="0" izz="0.00000"/>
		</inertial>
	</link>
	<link name="Burner 3">
		<inertial>
			<origin rpy="0.00000 -0.00000 0.00000" xyz="0.00000 0.00000 0.00000"/>
			<mass value="0.01000"/>
			<inertia ixx="0.00003" ixy="0" ixz="0" iyy="0.00003" iyz="0" izz="0.00005"/>
		</inertial>
		<collision>
			<origin rpy="0.00000 -0.00000 0.00000" xyz="0.00000 0.00000 0.00000"/>
			<geometry>
				<cylinder length="0.02000" radius="0.10000"/>
			</geometry>
		</collision>
	</link>
	<link name="link0_18">
		<inertial>
			<origin rpy="0.00000 -0.00000 0.00000" xyz="0.00000 0.00000 0.00000"/>
			<mass value="0.00000"/>
			<inertia ixx="0.00000" ixy="0" ixz="0" iyy="0.00000" iyz="0" izz="0.00000"/>
		</inertial>
	</link>
	<link name="knob 4">
		<inertial>
			<origin rpy="0.00000 -0.00000 0.00000" xyz="0.00000 0.00000 0.00000"/>
			<mass value="0.46703"/>
			<inertia ixx="0.00059" ixy="0" ixz="0" iyy="0.00049" iyz="0" izz="0.00088"/>
		</inertial>
		<collision>
			<origin rpy="0.00000 -0.00000 0.00000" xyz="0.00000 0.00000 0.03800"/>
			<geometry>
				<box size="0.02800 0.09600 0.03600"/>
			</geometry>
		</collision>
		<collision>
			<origin rpy="0.00000 -0.00000 0.00000" xyz="0.00000 0.00000 0.01300"/>
			<geometry>
				<cylinder length="0.01600" radius="0.05000"/>
			</geometry>
		</collision>
		<collision>
			<origin rpy="0.00000 -0.00000 0.00000" xyz="0.00000 0.04800 0.03700"/>
			<geometry>
				<cylinder length="0.03600" radius="0.01400"/>
			</geometry>
		</collision>
		<collision>
			<origin rpy="0.00000 -0.00000 0.00000" xyz="0.00000 0.00000 0.03800"/>
			<geometry>
				<box size="0.02800 0.09600 0.03600"/>
			</geometry>
		</collision>
		<collision>
			<origin rpy="0.00000 -0.00000 0.00000" xyz="0.00000 0.00000 0.01300"/>
			<geometry>
				<cylinder length="0.01600" radius="0.05000"/>
			</geometry>
		</collision>
	</link>
	<link name="link0_20">
		<inertial>
			<origin rpy="0.00000 -0.00000 0.00000" xyz="0.00000 0.00000 0.00000"/>
			<mass value="0.00000"/>
			<inertia ixx="0.00000" ixy="0" ixz="0" iyy="0.00000" iyz="0" izz="0.00000"/>
		</inertial>
	</link>
	<link name="Burner 4">
		<inertial>
			<origin rpy="0.00000 -0.00000 0.00000" xyz="0.00000 0.00000 0.00000"/>
			<mass value="0.01000"/>
			<inertia ixx="0.00003" ixy="0" ixz="0" iyy="0.00003" iyz="0" izz="0.00005"/>
		</inertial>
		<collision>
			<origin rpy="0.00000 -0.00000 0.00000" xyz="0.00000 0.00000 0.00000"/>
			<geometry>
				<cylinder length="0.02000" radius="0.10000"/>
			</geometry>
		</collision>
	</link>
	<link name="hoodroot">
		<inertial>
			<origin rpy="0.00000 -0.00000 0.00000" xyz="0.00000 0.00000 0.00000"/>
			<mass value="161.92511"/>
			<inertia ixx="9.01027" ixy="0" ixz="0" iyy="17.15821" iyz="0" izz="23.44716"/>
		</inertial>
		<collision>
			<origin rpy="0.00000 -0.00000 0.00000" xyz="-0.10000 -0.28960 -2.32900"/>
			<geometry>
				<mesh filename="unknown_file" scale="1.00000 1.00000 1.00000"/>
			</geometry>
		</collision>
		<collision>
			<origin rpy="0.00000 -0.00000 0.00000" xyz="0.00000 0.07300 -0.04600"/>
			<geometry>
				<box size="1.00400 0.67200 0.24000"/>
			</geometry>
		</collision>
	</link>
	<link name="lightswitchbaseroot">
		<inertial>
			<origin rpy="0.00000 -0.00000 0.00000" xyz="0.00000 0.00000 0.00000"/>
			<mass value="0.00000"/>
			<inertia ixx="0.00000" ixy="0" ixz="0" iyy="0.00000" iyz="0" izz="0.00000"/>
		</inertial>
		<collision>
			<origin rpy="0.00000 -0.00000 0.00000" xyz="0.00000 -0.01230 0.00000"/>
			<geometry>
				<mesh filename="unknown_file" scale="1.00000 1.00000 1.00000"/>
			</geometry>
		</collision>
	</link>
	<link name="link0_24">
		<inertial>
			<origin rpy="0.00000 -0.00000 0.00000" xyz="0.00000 0.00000 0.00000"/>
			<mass value="0.00000"/>
			<inertia ixx="0.00000" ixy="0" ixz="0" iyy="0.00000" iyz="0" izz="0.00000"/>
		</inertial>
	</link>
	<link name="lightswitchroot">
		<inertial>
			<origin rpy="0.00000 -0.00000 0.00000" xyz="-0.00460 0.35000 0.01310"/>
			<mass value="0.10000"/>
			<inertia ixx="0.00012" ixy="0" ixz="0" iyy="0.00012" iyz="0" izz="0.00003"/>
		</inertial>
		<collision>
			<origin rpy="0.00000 -0.00000 0.00000" xyz="0.02520 -0.06000 0.00000"/>
			<geometry>
				<capsule length="0.07000" radius="0.02000"/>
			</geometry>
		</collision>
		<collision>
			<origin rpy="0.00000 -0.00000 0.00000" xyz="0.02630 -0.06500 0.00000"/>
			<geometry>
				<capsule length="0.06000" radius="0.02100"/>
			</geometry>
		</collision>
	</link>
	<link name="link0_26">
		<inertial>
			<origin rpy="0.00000 -0.00000 0.00000" xyz="0.00000 0.00000 0.00000"/>
			<mass value="0.00000"/>
			<inertia ixx="0.00000" ixy="0" ixz="0" iyy="0.00000" iyz="0" izz="0.00000"/>
		</inertial>
	</link>
	<link name="lightblock_hinge">
		<inertial>
			<origin rpy="0.00000 -0.00000 0.00000" xyz="-0.00460 0.35000 0.01310"/>
			<mass value="0.01000"/>
			<inertia ixx="0.00030" ixy="0" ixz="0" iyy="0.00053" iyz="0" izz="0.00083"/>
		</inertial>
		<collision>
			<origin rpy="0.00000 -0.00000 0.00000" xyz="-0.00800 0.40000 -0.01000"/>
			<geometry>
				<box size="0.80000 0.60000 0.03000"/>
			</geometry>
		</collision>
	</link>
	<link name="backwall">
		<inertial>
			<origin rpy="0.00000 -0.00000 0.00000" xyz="0.00000 0.00000 0.00000"/>
			<mass value="0.00000"/>
			<inertia ixx="0.00000" ixy="0" ixz="0" iyy="0.00000" iyz="0" izz="0.00000"/>
		</inertial>
	</link>
	<link name="wallroot">
		<inertial>
			<origin rpy="0.00000 -0.00000 0.00000" xyz="0.00000 0.00000 0.00000"/>
			<mass value="1080.57602"/>
			<inertia ixx="131.97436" ixy="0" ixz="0" iyy="701.50995" iyz="0" izz="574.14605"/>
		</inertial>
		<collision>
			<origin rpy="0.00000 -0.00000 0.00000" xyz="-0.11000 0.06000 0.60000"/>
			<geometry>
				<box size="2.52000 0.14000 1.20000"/>
			</geometry>
		</collision>
		<collision>
			<origin rpy="0.00000 -0.00000 0.00000" xyz="-0.11000 0.06000 0.14500"/>
			<geometry>
				<box size="2.52000 0.16000 0.29000"/>
			</geometry>
		</collision>
		<collision>
			<origin rpy="0.00000 -0.00000 0.00000" xyz="-0.11000 0.06000 0.60000"/>
			<geometry>
				<box size="2.52000 0.14000 1.20000"/>
			</geometry>
		</collision>
		<collision>
			<origin rpy="0.00000 -0.00000 0.00000" xyz="-0.11000 0.06000 0.14500"/>
			<geometry>
				<box size="2.52000 0.16000 0.29000"/>
			</geometry>
		</collision>
	</link>
	<link name="wall2">
		<inertial>
			<origin rpy="0.00000 -0.00000 0.00000" xyz="0.00000 0.00000 0.00000"/>
			<mass value="925.35042"/>
			<inertia ixx="113.01614" ixy="0" ixz="0" iyy="470.15236" iyz="0" izz="361.08438"/>
		</inertial>
		<collision>
			<origin rpy="0.00000 -0.00000 0.00000" xyz="0.04400 0.06000 0.60000"/>
			<geometry>
				<box size="2.15800 0.14000 1.20000"/>
			</geometry>
		</collision>
		<collision>
			<origin rpy="0.00000 -0.00000 0.00000" xyz="0.04400 0.06000 0.14500"/>
			<geometry>
				<box size="2.15800 0.16000 0.29000"/>
			</geometry>
		</collision>
		<collision>
			<origin rpy="0.00000 -0.00000 0.00000" xyz="0.04400 0.06000 0.60000"/>
			<geometry>
				<box size="2.15800 0.14000 1.20000"/>
			</geometry>
		</collision>
		<collision>
			<origin rpy="0.00000 -0.00000 0.00000" xyz="0.04400 0.06000 0.14500"/>
			<geometry>
				<box size="2.15800 0.16000 0.29000"/>
			</geometry>
		</collision>
	</link>
	<link name="slidecabinet">
		<inertial>
			<origin rpy="0.00000 -0.00000 0.00000" xyz="0.00000 0.00000 0.00000"/>
			<mass value="0.00000"/>
			<inertia ixx="0.00000" ixy="0" ixz="0" iyy="0.00000" iyz="0" izz="0.00000"/>
		</inertial>
	</link>
	<link name="slide">
		<inertial>
			<origin rpy="0.00000 -0.00000 0.00000" xyz="0.00000 0.00000 0.00000"/>
			<mass value="289.26721"/>
			<inertia ixx="12.53491" ixy="0" ixz="0" iyy="23.29575" iyz="0" izz="28.11687"/>
		</inertial>
		<collision>
			<origin rpy="0.00000 -0.00000 0.00000" xyz="-0.22500 0.00000 -0.18000"/>
			<geometry>
				<box size="0.44600 0.60000 0.04000"/>
			</geometry>
		</collision>
		<collision>
			<origin rpy="0.00000 -0.00000 0.00000" xyz="0.22400 0.00000 0.00000"/>
			<geometry>
				<box size="0.45200 0.60000 0.40000"/>
			</geometry>
		</collision>
		<collision>
			<origin rpy="0.00000 -0.00000 0.00000" xyz="-0.22500 0.00000 0.18000"/>
			<geometry>
				<box size="0.44600 0.60000 0.04000"/>
			</geometry>
		</collision>
		<collision>
			<origin rpy="0.00000 -0.00000 0.00000" xyz="-0.42600 0.00000 0.00000"/>
			<geometry>
				<box size="0.04400 0.60000 0.32000"/>
			</geometry>
		</collision>
		<collision>
			<origin rpy="0.00000 -0.00000 0.00000" xyz="-0.20000 0.27600 0.00000"/>
			<geometry>
				<box size="0.42000 0.04800 0.32000"/>
			</geometry>
		</collision>
		<collision>
			<origin rpy="0.00000 -0.00000 0.00000" xyz="-0.22500 0.00000 -0.18000"/>
			<geometry>
				<box size="0.44600 0.60000 0.04000"/>
			</geometry>
		</collision>
		<collision>
			<origin rpy="0.00000 -0.00000 0.00000" xyz="0.22400 0.00000 0.00000"/>
			<geometry>
				<box size="0.45200 0.60000 0.40000"/>
			</geometry>
		</collision>
		<collision>
			<origin rpy="0.00000 -0.00000 0.00000" xyz="-0.22500 0.00000 0.18000"/>
			<geometry>
				<box size="0.44600 0.60000 0.04000"/>
			</geometry>
		</collision>
		<collision>
			<origin rpy="0.00000 -0.00000 0.00000" xyz="-0.42600 0.00000 0.00000"/>
			<geometry>
				<box size="0.04400 0.60000 0.32000"/>
			</geometry>
		</collision>
		<collision>
			<origin rpy="0.00000 -0.00000 0.00000" xyz="-0.20000 0.27600 0.00000"/>
			<geometry>
				<box size="0.40000 0.04800 0.32000"/>
			</geometry>
		</collision>
	</link>
	<link name="link0_33">
		<inertial>
			<origin rpy="0.00000 -0.00000 0.00000" xyz="0.00000 0.00000 0.00000"/>
			<mass value="0.00000"/>
			<inertia ixx="0.00000" ixy="0" ixz="0" iyy="0.00000" iyz="0" izz="0.00000"/>
		</inertial>
	</link>
	<link name="slidelink">
		<inertial>
			<origin rpy="0.00000 -0.00000 0.00000" xyz="0.00000 0.00000 0.00000"/>
			<mass value="22.50792"/>
			<inertia ixx="0.33035" ixy="0" ixz="0" iyy="0.66511" iyz="0" izz="0.42488"/>
		</inertial>
		<collision>
			<origin rpy="0.00000 -0.00000 0.00000" xyz="-0.18300 -0.06000 -0.11400"/>
			<geometry>
				<cylinder length="0.10600" radius="0.01900"/>
			</geometry>
		</collision>
		<collision>
			<origin rpy="0.00000 -0.00000 0.00000" xyz="-0.18300 -0.06000 0.11400"/>
			<geometry>
				<cylinder length="0.10600" radius="0.01900"/>
			</geometry>
		</collision>
		<collision>
			<origin rpy="0.00000 -0.00000 0.00000" xyz="-0.18300 -0.12300 0.00000"/>
			<geometry>
				<cylinder length="0.31800" radius="0.02200"/>
			</geometry>
		</collision>
		<collision>
			<origin rpy="0.00000 -0.00000 0.00000" xyz="0.00000 -0.02000 0.00000"/>
			<geometry>
				<box size="0.45000 0.06000 0.39000"/>
			</geometry>
		</collision>
		<collision>
			<origin rpy="0.00000 -0.00000 0.00000" xyz="0.00000 -0.02000 0.00000"/>
			<geometry>
				<box size="0.45000 0.06000 0.39000"/>
			</geometry>
		</collision>
		<collision>
			<origin rpy="0.00000 -0.00000 0.00000" xyz="-0.18300 -0.06000 -0.11400"/>
			<geometry>
				<cylinder length="0.10600" radius="0.01900"/>
			</geometry>
		</collision>
		<collision>
			<origin rpy="0.00000 -0.00000 0.00000" xyz="-0.18300 -0.06000 0.11400"/>
			<geometry>
				<cylinder length="0.10600" radius="0.01900"/>
			</geometry>
		</collision>
		<collision>
			<origin rpy="0.00000 -0.00000 0.00000" xyz="-0.18300 -0.12300 0.00000"/>
			<geometry>
				<cylinder length="0.31800" radius="0.02200"/>
			</geometry>
		</collision>
	</link>
	<link name="hingecabinet">
		<inertial>
			<origin rpy="0.00000 -0.00000 0.00000" xyz="0.00000 0.00000 0.00000"/>
			<mass value="0.00000"/>
			<inertia ixx="0.00000" ixy="0" ixz="0" iyy="0.00000" iyz="0" izz="0.00000"/>
		</inertial>
	</link>
	<link name="hingecab">
		<inertial>
			<origin rpy="0.00000 -0.00000 0.00000" xyz="0.00000 0.00000 0.00000"/>
			<mass value="154.62400"/>
			<inertia ixx="6.70037" ixy="0" ixz="0" iyy="10.30827" iyz="0" izz="12.88533"/>
		</inertial>
		<collision>
			<origin rpy="0.00000 -0.00000 0.00000" xyz="0.00000 0.00000 0.00000"/>
			<geometry>
				<box size="0.08000 0.60000 0.40000"/>
			</geometry>
		</collision>
		<collision>
			<origin rpy="0.00000 -0.00000 0.00000" xyz="0.38000 0.00000 0.00000"/>
			<geometry>
				<box size="0.04000 0.60000 0.40000"/>
			</geometry>
		</collision>
		<collision>
			<origin rpy="0.00000 -0.00000 0.00000" xyz="-0.38000 0.00000 0.00000"/>
			<geometry>
				<box size="0.04000 0.60000 0.40000"/>
			</geometry>
		</collision>
		<collision>
			<origin rpy="0.00000 -0.00000 0.00000" xyz="-0.20000 0.00000 0.18000"/>
			<geometry>
				<box size="0.32000 0.60000 0.04000"/>
			</geometry>
		</collision>
		<collision>
			<origin rpy="0.00000 -0.00000 0.00000" xyz="-0.20000 0.00000 -0.18000"/>
			<geometry>
				<box size="0.32000 0.60000 0.04000"/>
			</geometry>
		</collision>
		<collision>
			<origin rpy="0.00000 -0.00000 0.00000" xyz="0.20000 0.00000 -0.18000"/>
			<geometry>
				<box size="0.32000 0.60000 0.04000"/>
			</geometry>
		</collision>
		<collision>
			<origin rpy="0.00000 -0.00000 0.00000" xyz="0.20000 0.00000 0.18000"/>
			<geometry>
				<box size="0.32000 0.60000 0.04000"/>
			</geometry>
		</collision>
		<collision>
			<origin rpy="0.00000 -0.00000 0.00000" xyz="-0.20000 0.28000 0.00000"/>
			<geometry>
				<box size="0.32000 0.04000 0.32000"/>
			</geometry>
		</collision>
		<collision>
			<origin rpy="0.00000 -0.00000 0.00000" xyz="0.20000 0.28000 0.00000"/>
			<geometry>
				<box size="0.32000 0.04000 0.32000"/>
			</geometry>
		</collision>
		<collision>
			<origin rpy="0.00000 -0.00000 0.00000" xyz="0.00000 0.00000 0.00000"/>
			<geometry>
				<box size="0.08000 0.60000 0.40000"/>
			</geometry>
		</collision>
		<collision>
			<origin rpy="0.00000 -0.00000 0.00000" xyz="0.38000 0.00000 0.00000"/>
			<geometry>
				<box size="0.04000 0.60000 0.40000"/>
			</geometry>
		</collision>
		<collision>
			<origin rpy="0.00000 -0.00000 0.00000" xyz="-0.38000 0.00000 0.00000"/>
			<geometry>
				<box size="0.04000 0.60000 0.40000"/>
			</geometry>
		</collision>
		<collision>
			<origin rpy="0.00000 -0.00000 0.00000" xyz="-0.20000 0.00000 0.18000"/>
			<geometry>
				<box size="0.32000 0.60000 0.04000"/>
			</geometry>
		</collision>
		<collision>
			<origin rpy="0.00000 -0.00000 0.00000" xyz="-0.20000 0.00000 -0.18000"/>
			<geometry>
				<box size="0.32000 0.60000 0.04000"/>
			</geometry>
		</collision>
		<collision>
			<origin rpy="0.00000 -0.00000 0.00000" xyz="0.20000 0.00000 -0.18000"/>
			<geometry>
				<box size="0.32000 0.60000 0.04000"/>
			</geometry>
		</collision>
		<collision>
			<origin rpy="0.00000 -0.00000 0.00000" xyz="0.20000 0.00000 0.18000"/>
			<geometry>
				<box size="0.32000 0.60000 0.04000"/>
			</geometry>
		</collision>
		<collision>
			<origin rpy="0.00000 -0.00000 0.00000" xyz="-0.20000 0.28000 0.00000"/>
			<geometry>
				<box size="0.32000 0.04000 0.32000"/>
			</geometry>
		</collision>
		<collision>
			<origin rpy="0.00000 -0.00000 0.00000" xyz="0.20000 0.28000 0.00000"/>
			<geometry>
				<box size="0.32000 0.04000 0.32000"/>
			</geometry>
		</collision>
	</link>
	<link name="link0_37">
		<inertial>
			<origin rpy="0.00000 -0.00000 0.00000" xyz="0.00000 0.00000 0.00000"/>
			<mass value="0.00000"/>
			<inertia ixx="0.00000" ixy="0" ixz="0" iyy="0.00000" iyz="0" izz="0.00000"/>
		</inertial>
	</link>
	<link name="hingeleftdoor">
		<inertial>
			<origin rpy="0.00000 -0.00000 0.00000" xyz="0.00000 0.00000 0.00000"/>
			<mass value="19.98200"/>
			<inertia ixx="0.31176" ixy="0" ixz="0" iyy="0.51453" iyz="0" izz="0.29344"/>
		</inertial>
		<collision>
			<origin rpy="0.00000 -0.00000 0.00000" xyz="0.30200 -0.12800 0.00000"/>
			<geometry>
				<cylinder length="0.32000" radius="0.02200"/>
			</geometry>
		</collision>
		<collision>
			<origin rpy="0.00000 -0.00000 0.00000" xyz="0.30200 -0.06100 0.11400"/>
			<geometry>
				<cylinder length="0.10600" radius="0.01900"/>
			</geometry>
		</collision>
		<collision>
			<origin rpy="0.00000 -0.00000 0.00000" xyz="0.30200 -0.06100 -0.11400"/>
			<geometry>
				<cylinder length="0.10600" radius="0.01900"/>
			</geometry>
		</collision>
		<collision>
			<origin rpy="0.00000 -0.00000 0.00000" xyz="0.18400 -0.01500 0.00000"/>
			<geometry>
				<box size="0.38600 0.06000 0.40000"/>
			</geometry>
		</collision>
		<collision>
			<origin rpy="0.00000 -0.00000 0.00000" xyz="0.18400 -0.01500 0.00000"/>
			<geometry>
				<box size="0.38600 0.06000 0.40000"/>
			</geometry>
		</collision>
		<collision>
			<origin rpy="0.00000 -0.00000 0.00000" xyz="0.30200 -0.12800 0.00000"/>
			<geometry>
				<cylinder length="0.32000" radius="0.02200"/>
			</geometry>
		</collision>
		<collision>
			<origin rpy="0.00000 -0.00000 0.00000" xyz="0.30200 -0.06100 0.11400"/>
			<geometry>
				<cylinder length="0.10600" radius="0.01900"/>
			</geometry>
		</collision>
		<collision>
			<origin rpy="0.00000 -0.00000 0.00000" xyz="0.30200 -0.06100 -0.11400"/>
			<geometry>
				<cylinder length="0.10600" radius="0.01900"/>
			</geometry>
		</collision>
	</link>
	<link name="link0_39">
		<inertial>
			<origin rpy="0.00000 -0.00000 0.00000" xyz="0.00000 0.00000 0.00000"/>
			<mass value="0.00000"/>
			<inertia ixx="0.00000" ixy="0" ixz="0" iyy="0.00000" iyz="0" izz="0.00000"/>
		</inertial>
	</link>
	<link name="hingerightdoor">
		<inertial>
			<origin rpy="0.00000 -0.00000 0.00000" xyz="0.00000 0.00000 0.00000"/>
			<mass value="19.98200"/>
			<inertia ixx="0.31176" ixy="0" ixz="0" iyy="0.51453" iyz="0" izz="0.29344"/>
		</inertial>
		<collision>
			<origin rpy="0.00000 -0.00000 0.00000" xyz="-0.18500 -0.01500 0.00000"/>
			<geometry>
				<box size="0.38600 0.06000 0.40000"/>
			</geometry>
		</collision>
		<collision>
			<origin rpy="0.00000 -0.00000 0.00000" xyz="-0.30200 -0.12800 0.00000"/>
			<geometry>
				<cylinder length="0.32000" radius="0.02200"/>
			</geometry>
		</collision>
		<collision>
			<origin rpy="0.00000 -0.00000 0.00000" xyz="-0.30200 -0.06100 -0.11400"/>
			<geometry>
				<cylinder length="0.10600" radius="0.01900"/>
			</geometry>
		</collision>
		<collision>
			<origin rpy="0.00000 -0.00000 0.00000" xyz="-0.30200 -0.06100 0.11400"/>
			<geometry>
				<cylinder length="0.10600" radius="0.01900"/>
			</geometry>
		</collision>
		<collision>
			<origin rpy="0.00000 -0.00000 0.00000" xyz="-0.30200 -0.12800 0.00000"/>
			<geometry>
				<cylinder length="0.32000" radius="0.02200"/>
			</geometry>
		</collision>
		<collision>
			<origin rpy="0.00000 -0.00000 0.00000" xyz="-0.30200 -0.06100 -0.11400"/>
			<geometry>
				<cylinder length="0.10600" radius="0.01900"/>
			</geometry>
		</collision>
		<collision>
			<origin rpy="0.00000 -0.00000 0.00000" xyz="-0.30200 -0.06100 0.11400"/>
			<geometry>
				<cylinder length="0.10600" radius="0.01900"/>
			</geometry>
		</collision>
		<collision>
			<origin rpy="0.00000 -0.00000 0.00000" xyz="-0.18500 -0.01500 0.00000"/>
			<geometry>
				<box size="0.38600 0.06000 0.40000"/>
			</geometry>
		</collision>
	</link>
	<link name="microwave">
		<inertial>
			<origin rpy="0.00000 -0.00000 0.00000" xyz="0.00000 0.00000 0.00000"/>
			<mass value="0.00000"/>
			<inertia ixx="0.00000" ixy="0" ixz="0" iyy="0.00000" iyz="0" izz="0.00000"/>
		</inertial>
	</link>
	<link name="microroot">
		<inertial>
			<origin rpy="0.00000 -0.00000 0.00000" xyz="0.00000 0.00000 0.00000"/>
			<mass value="65.41956"/>
			<inertia ixx="2.64995" ixy="0" ixz="0" iyy="4.37479" iyz="0" izz="4.75932"/>
		</inertial>
		<collision>
			<origin rpy="0.00000 -0.00000 0.00000" xyz="0.00000 0.00000 0.00000"/>
			<geometry>
				<mesh filename="unknown_file" scale="1.00000 1.00000 1.00000"/>
			</geometry>
		</collision>
		<collision>
			<origin rpy="0.00000 -0.00000 0.00000" xyz="0.00000 0.00000 0.00000"/>
			<geometry>
				<mesh filename="unknown_file" scale="1.00000 1.00000 1.00000"/>
			</geometry>
		</collision>
		<collision>
			<origin rpy="0.00000 -0.00000 0.00000" xyz="0.00000 0.00000 0.00000"/>
			<geometry>
				<mesh filename="unknown_file" scale="1.00000 1.00000 1.00000"/>
			</geometry>
		</collision>
		<collision>
			<origin rpy="0.00000 -0.00000 0.00000" xyz="-0.31600 0.02300 0.18700"/>
			<geometry>
				<box size="0.05800 0.39800 0.37400"/>
			</geometry>
		</collision>
		<collision>
			<origin rpy="0.00000 -0.00000 0.00000" xyz="0.23600 0.02300 0.18700"/>
			<geometry>
				<box size="0.21800 0.39800 0.37400"/>
			</geometry>
		</collision>
		<collision>
			<origin rpy="0.00000 -0.00000 0.00000" xyz="-0.08100 0.19100 0.18700"/>
			<geometry>
				<box size="0.41400 0.06000 0.37400"/>
			</geometry>
		</collision>
		<collision>
			<origin rpy="0.00000 -0.00000 0.00000" xyz="-0.08000 -0.00700 0.35500"/>
			<geometry>
				<box size="0.41400 0.33800 0.03800"/>
			</geometry>
		</collision>
		<collision>
			<origin rpy="0.00000 -0.00000 0.00000" xyz="-0.08000 -0.00800 0.02400"/>
			<geometry>
				<box size="0.41400 0.33600 0.04800"/>
			</geometry>
		</collision>
		<collision>
			<origin rpy="0.00000 -0.00000 0.00000" xyz="0.26000 -0.19700 0.18700"/>
			<geometry>
				<box size="0.17000 0.04800 0.37400"/>
			</geometry>
		</collision>
	</link>
	<link name="link0_43">
		<inertial>
			<origin rpy="0.00000 -0.00000 0.00000" xyz="0.00000 0.00000 0.00000"/>
			<mass value="0.00000"/>
			<inertia ixx="0.00000" ixy="0" ixz="0" iyy="0.00000" iyz="0" izz="0.00000"/>
		</inertial>
	</link>
	<link name="microdoorroot">
		<inertial>
			<origin rpy="0.00000 -0.00000 0.00000" xyz="0.00000 0.00000 0.00000"/>
			<mass value="10.35579"/>
			<inertia ixx="0.19522" ixy="0" ixz="0" iyy="0.48147" iyz="0" izz="0.33278"/>
		</inertial>
		<collision>
			<origin rpy="0.00000 -0.00000 0.00000" xyz="0.34500 0.17600 -0.19200"/>
			<geometry>
				<mesh filename="unknown_file" scale="1.00000 1.00000 1.00000"/>
			</geometry>
		</collision>
		<collision>
			<origin rpy="0.00000 -0.00000 0.00000" xyz="0.34500 0.17600 -0.19200"/>
			<geometry>
				<mesh filename="unknown_file" scale="1.00000 1.00000 1.00000"/>
			</geometry>
		</collision>
		<collision>
			<origin rpy="0.00000 -0.00000 0.00000" xyz="0.47500 -0.10800 0.00000"/>
			<geometry>
				<capsule length="0.26000" radius="0.02000"/>
			</geometry>
		</collision>
		<collision>
			<origin rpy="0.00000 -0.00000 0.00000" xyz="0.47500 -0.07500 0.13000"/>
			<geometry>
				<capsule length="0.06000" radius="0.02000"/>
			</geometry>
		</collision>
		<collision>
			<origin rpy="0.00000 -0.00000 0.00000" xyz="0.47500 -0.07500 -0.13000"/>
			<geometry>
				<capsule length="0.06000" radius="0.02000"/>
			</geometry>
		</collision>
		<collision>
			<origin rpy="0.00000 -0.00000 0.00000" xyz="0.47500 -0.10800 0.00000"/>
			<geometry>
				<capsule length="0.26000" radius="0.02000"/>
			</geometry>
		</collision>
		<collision>
			<origin rpy="0.00000 -0.00000 0.00000" xyz="0.47500 -0.07500 0.13000"/>
			<geometry>
				<capsule length="0.06000" radius="0.02000"/>
			</geometry>
		</collision>
		<collision>
			<origin rpy="0.00000 -0.00000 0.00000" xyz="0.47500 -0.07500 -0.13000"/>
			<geometry>
				<capsule length="0.06000" radius="0.02000"/>
			</geometry>
		</collision>
		<collision>
			<origin rpy="0.00000 -0.00000 0.00000" xyz="0.25900 -0.02600 0.00000"/>
			<geometry>
				<box size="0.51800 0.04800 0.37000"/>
			</geometry>
		</collision>
	</link>
	<joint name="jointfix_1_0" type="fixed">
		<parent link="desk"/>
		<child link="counters1"/>
		<dynamics damping="1.0" friction="0.0001"/>
		<origin rpy="0.00000 -0.00000 0.00000" xyz="0.00000 0.00000 0.00000"/>
		<axis xyz="0.00000 0.00000 0.00000"/>
	</joint>
	<joint name="jointfix_0_1" type="fixed">
		<parent link="counters1"/>
		<child link="counters"/>
		<dynamics damping="1.0" friction="0.0001"/>
		<origin rpy="0.00000 -0.00000 0.00000" xyz="0.00000 0.00000 0.00000"/>
		<axis xyz="0.00000 0.00000 0.00000"/>
	</joint>
	<joint name="jointfix_15_0" type="fixed">
		<parent link="desk"/>
		<child link="oven"/>
		<dynamics damping="1.0" friction="0.0001"/>
		<origin rpy="0.00000 -0.00000 0.00000" xyz="0.00000 0.00000 0.00000"/>
		<axis xyz="0.00000 0.00000 0.00000"/>
	</joint>
	<joint name="jointfix_10_3" type="fixed">
		<parent link="oven"/>
		<child link="ovenroot"/>
		<dynamics damping="1.0" friction="0.0001"/>
		<origin rpy="0.00000 -0.00000 0.00000" xyz="0.11500 -0.29210 0.98340"/>
		<axis xyz="0.00000 0.00000 0.00000"/>
	</joint>
	<joint name="knob_Joint_1" type="revolute">
		<parent link="ovenroot"/>
		<child link="link0_6"/>
		<limit effort="0.00000" lower="-1.57000" upper="0.00000" velocity="0.00000"/>
		<dynamics damping="1.0" friction="0.0001"/>
		<origin rpy="0.00000 -0.00000 0.00000" xyz="-0.14800 0.22000 1.24300"/>
		<axis xyz="0.00000 0.00000 1.00000"/>
	</joint>
	<joint name="jointfix_2_6" type="fixed">
		<parent link="link0_6"/>
		<child link="knob 1"/>
		<dynamics damping="1.0" friction="0.0001"/>
		<origin rpy="0.00000 -0.00000 0.00000" xyz="0.00000 0.00000 0.00000"/>
		<axis xyz="0.00000 0.00000 0.00000"/>
	</joint>
	<joint name="bottom_right_burner" type="prismatic">
		<parent link="ovenroot"/>
		<child link="link0_8"/>
		<limit effort="0.00000" lower="-0.00900" upper="0.00000" velocity="0.00000"/>
		<dynamics damping="1.0" friction="0.0001"/>
		<origin rpy="0.00000 -0.00000 0.00000" xyz="0.20600 -0.11900 0.61000"/>
		<axis xyz="0.00000 0.00000 -1.00000"/>
	</joint>
	<joint name="jointfix_3_8" type="fixed">
		<parent link="link0_8"/>
		<child link="Burner 1"/>
		<dynamics damping="1.0" friction="0.0001"/>
		<origin rpy="0.00000 -0.00000 0.00000" xyz="0.00000 0.00000 0.00000"/>
		<axis xyz="0.00000 0.00000 0.00000"/>
	</joint>
	<joint name="knob_Joint_2" type="revolute">
		<parent link="ovenroot"/>
		<child link="link0_10"/>
		<limit effort="0.00000" lower="-1.57000" upper="0.00000" velocity="0.00000"/>
		<dynamics damping="1.0" friction="0.0001"/>
		<origin rpy="0.00000 -0.00000 0.00000" xyz="-0.27100 0.22000 1.24300"/>
		<axis xyz="0.00000 0.00000 1.00000"/>
	</joint>
	<joint name="jointfix_4_10" type="fixed">
		<parent link="link0_10"/>
		<child link="knob 2"/>
		<dynamics damping="1.0" friction="0.0001"/>
		<origin rpy="0.00000 -0.00000 0.00000" xyz="0.00000 0.00000 0.00000"/>
		<axis xyz="0.00000 0.00000 0.00000"/>
	</joint>
	<joint name="bottom_left_burner" type="prismatic">
		<parent link="ovenroot"/>
		<child link="link0_12"/>
		<limit effort="0.00000" lower="-0.00900" upper="0.00000" velocity="0.00000"/>
		<dynamics damping="1.0" friction="0.0001"/>
		<origin rpy="0.00000 -0.00000 0.00000" xyz="-0.24000 -0.11900 0.61000"/>
		<axis xyz="0.00000 0.00000 -1.00000"/>
	</joint>
	<joint name="jointfix_5_12" type="fixed">
		<parent link="link0_12"/>
		<child link="Burner 2"/>
		<dynamics damping="1.0" friction="0.0001"/>
		<origin rpy="0.00000 -0.00000 0.00000" xyz="0.00000 0.00000 0.00000"/>
		<axis xyz="0.00000 0.00000 0.00000"/>
	</joint>
	<joint name="knob_Joint_3" type="revolute">
		<parent link="ovenroot"/>
		<child link="link0_14"/>
		<limit effort="0.00000" lower="-1.57000" upper="0.00000" velocity="0.00000"/>
		<dynamics damping="1.0" friction="0.0001"/>
		<origin rpy="0.00000 -0.00000 0.00000" xyz="-0.14800 0.22000 1.35700"/>
		<axis xyz="0.00000 0.00000 1.00000"/>
	</joint>
	<joint name="jointfix_6_14" type="fixed">
		<parent link="link0_14"/>
		<child link="knob 3"/>
		<dynamics damping="1.0" friction="0.0001"/>
		<origin rpy="0.00000 -0.00000 0.00000" xyz="0.00000 0.00000 0.00000"/>
		<axis xyz="0.00000 0.00000 0.00000"/>
	</joint>
	<joint name="top_right_burner" type="prismatic">
		<parent link="ovenroot"/>
		<child link="link0_16"/>
		<limit effort="0.00000" lower="-0.00900" upper="0.00000" velocity="0.00000"/>
		<dynamics damping="1.0" friction="0.0001"/>
		<origin rpy="0.00000 -0.00000 0.00000" xyz="0.20400 0.32200 0.61000"/>
		<axis xyz="0.00000 0.00000 -1.00000"/>
	</joint>
	<joint name="jointfix_7_16" type="fixed">
		<parent link="link0_16"/>
		<child link="Burner 3"/>
		<dynamics damping="1.0" friction="0.0001"/>
		<origin rpy="0.00000 -0.00000 0.00000" xyz="0.00000 0.00000 0.00000"/>
		<axis xyz="0.00000 0.00000 0.00000"/>
	</joint>
	<joint name="knob_Joint_4" type="revolute">
		<parent link="ovenroot"/>
		<child link="link0_18"/>
		<limit effort="0.00000" lower="-1.57000" upper="0.00000" velocity="0.00000"/>
		<dynamics damping="1.0" friction="0.0001"/>
		<origin rpy="0.00000 -0.00000 0.00000" xyz="-0.27100 0.22000 1.35700"/>
		<axis xyz="0.00000 0.00000 1.00000"/>
	</joint>
	<joint name="jointfix_8_18" type="fixed">
		<parent link="link0_18"/>
		<child link="knob 4"/>
		<dynamics damping="1.0" friction="0.0001"/>
		<origin rpy="0.00000 -0.00000 0.00000" xyz="0.00000 0.00000 0.00000"/>
		<axis xyz="0.00000 0.00000 0.00000"/>
	</joint>
	<joint name="top_left_burner" type="prismatic">
		<parent link="ovenroot"/>
		<child link="link0_20"/>
		<limit effort="0.00000" lower="-0.00900" upper="0.00000" velocity="0.00000"/>
		<dynamics damping="1.0" friction="0.0001"/>
		<origin rpy="0.00000 -0.00000 0.00000" xyz="-0.23700 0.32200 0.61000"/>
		<axis xyz="0.00000 0.00000 -1.00000"/>
	</joint>
	<joint name="jointfix_9_20" type="fixed">
		<parent link="link0_20"/>
		<child link="Burner 4"/>
		<dynamics damping="1.0" friction="0.0001"/>
		<origin rpy="0.00000 -0.00000 0.00000" xyz="0.00000 0.00000 0.00000"/>
		<axis xyz="0.00000 0.00000 0.00000"/>
	</joint>
	<joint name="jointfix_14_3" type="fixed">
		<parent link="oven"/>
		<child link="hoodroot"/>
		<dynamics damping="1.0" friction="0.0001"/>
		<origin rpy="0.00000 -0.00000 0.00000" xyz="0.10000 0.18800 2.33000"/>
		<axis xyz="0.00000 0.00000 0.00000"/>
	</joint>
	<joint name="jointfix_12_21" type="fixed">
		<parent link="hoodroot"/>
		<child link="lightswitchbaseroot"/>
		<dynamics damping="1.0" friction="0.0001"/>
		<origin rpy="0.00000 -0.00000 0.00000" xyz="-0.40000 -0.24730 -0.05000"/>
		<axis xyz="0.00000 0.00000 0.00000"/>
	</joint>
	<joint name="light_switch" type="revolute">
		<parent link="lightswitchbaseroot"/>
		<child link="link0_24"/>
		<limit effort="0.00000" lower="-0.70000" upper="0.00000" velocity="0.00000"/>
		<dynamics damping="1.0" friction="0.0001"/>
		<origin rpy="0.00000 -0.00000 0.00000" xyz="0.00000 0.00000 0.00000"/>
		<axis xyz="0.00000 0.00000 1.00000"/>
	</joint>
	<joint name="jointfix_11_24" type="fixed">
		<parent link="link0_24"/>
		<child link="lightswitchroot"/>
		<dynamics damping="1.0" friction="0.0001"/>
		<origin rpy="0.00000 -0.00000 0.00000" xyz="0.00000 0.00000 0.00000"/>
		<axis xyz="0.00000 0.00000 0.00000"/>
	</joint>
	<joint name="light_joint" type="prismatic">
		<parent link="hoodroot"/>
		<child link="link0_26"/>
		<limit effort="0.00000" lower="-0.05000" upper="0.00000" velocity="0.00000"/>
		<dynamics damping="1.0" friction="0.0001"/>
		<origin rpy="0.00000 -0.00000 0.00000" xyz="-0.00440 -0.30000 -0.13610"/>
		<axis xyz="0.00000 0.00000 -1.00000"/>
	</joint>
	<joint name="jointfix_13_26" type="fixed">
		<parent link="link0_26"/>
		<child link="lightblock_hinge"/>
		<dynamics damping="1.0" friction="0.0001"/>
		<origin rpy="0.00000 -0.00000 0.00000" xyz="0.00000 0.00000 0.00000"/>
		<axis xyz="0.00000 0.00000 0.00000"/>
	</joint>
	<joint name="jointfix_18_0" type="fixed">
		<parent link="desk"/>
		<child link="backwall"/>
		<dynamics damping="1.0" friction="0.0001"/>
		<origin rpy="0.00000 -0.00000 0.00000" xyz="0.00000 0.00000 0.00000"/>
		<axis xyz="0.00000 0.00000 0.00000"/>
	</joint>
	<joint name="jointfix_16_27" type="fixed">
		<parent link="backwall"/>
		<child link="wallroot"/>
		<dynamics damping="1.0" friction="0.0001"/>
		<origin rpy="0.00000 -0.00000 0.00000" xyz="0.05900 0.58400 1.58700"/>
		<axis xyz="0.00000 0.00000 0.00000"/>
	</joint>
	<joint name="jointfix_17_27" type="fixed">
		<parent link="backwall"/>
		<child link="wall2"/>
		<dynamics damping="1.0" friction="0.0001"/>
		<origin rpy="0.00000 -0.00000 0.00000" xyz="-1.30500 -0.54600 1.58700"/>
		<axis xyz="0.00000 0.00000 0.00000"/>
	</joint>
	<joint name="jointfix_21_0" type="fixed">
		<parent link="desk"/>
		<child link="slidecabinet"/>
		<dynamics damping="1.0" friction="0.0001"/>
		<origin rpy="0.00000 -0.00000 0.00000" xyz="0.40000 0.30000 2.60000"/>
		<axis xyz="0.00000 0.00000 0.00000"/>
	</joint>
	<joint name="jointfix_20_30" type="fixed">
		<parent link="slidecabinet"/>
		<child link="slide"/>
		<dynamics damping="1.0" friction="0.0001"/>
		<origin rpy="0.00000 -0.00000 0.00000" xyz="0.00000 0.00000 0.00000"/>
		<axis xyz="0.00000 0.00000 0.00000"/>
	</joint>
	<joint name="slide_cabinet" type="prismatic">
		<parent link="slide"/>
		<child link="link0_33"/>
		<limit effort="0.00000" lower="0.00000" upper="0.44000" velocity="0.00000"/>
		<dynamics damping="1.0" friction="0.0001"/>
		<origin rpy="0.00000 -0.00000 0.00000" xyz="-0.22500 -0.32000 0.00000"/>
		<axis xyz="1.00000 0.00000 0.00000"/>
	</joint>
	<joint name="jointfix_19_33" type="fixed">
		<parent link="link0_33"/>
		<child link="slidelink"/>
		<dynamics damping="1.0" friction="0.0001"/>
		<origin rpy="0.00000 -0.00000 0.00000" xyz="0.00000 0.00000 0.00000"/>
		<axis xyz="0.00000 0.00000 0.00000"/>
	</joint>
	<joint name="jointfix_25_0" type="fixed">
		<parent link="desk"/>
		<child link="hingecabinet"/>
		<dynamics damping="1.0" friction="0.0001"/>
		<origin rpy="0.00000 -0.00000 0.00000" xyz="-0.50400 0.28000 2.60000"/>
		<axis xyz="0.00000 0.00000 0.00000"/>
	</joint>
	<joint name="jointfix_24_34" type="fixed">
		<parent link="hingecabinet"/>
		<child link="hingecab"/>
		<dynamics damping="1.0" friction="0.0001"/>
		<origin rpy="0.00000 -0.00000 0.00000" xyz="0.00000 0.00000 0.00000"/>
		<axis xyz="0.00000 0.00000 0.00000"/>
	</joint>
	<joint name="left_hinge_cabinet" type="revolute">
		<parent link="hingecab"/>
		<child link="link0_37"/>
		<limit effort="0.00000" lower="-1.57000" upper="0.00000" velocity="0.00000"/>
		<dynamics damping="1.0" friction="0.0001"/>
		<origin rpy="0.00000 -0.00000 0.00000" xyz="-0.38000 -0.32000 0.00000"/>
		<axis xyz="0.00000 0.00000 1.00000"/>
	</joint>
	<joint name="jointfix_22_37" type="fixed">
		<parent link="link0_37"/>
		<child link="hingeleftdoor"/>
		<dynamics damping="1.0" friction="0.0001"/>
		<origin rpy="0.00000 -0.00000 0.00000" xyz="0.00000 0.00000 0.00000"/>
		<axis xyz="0.00000 0.00000 0.00000"/>
	</joint>
	<joint name="right_hinge_cabinet" type="revolute">
		<parent link="hingecab"/>
		<child link="link0_39"/>
		<limit effort="0.00000" lower="0.00000" upper="1.57000" velocity="0.00000"/>
		<dynamics damping="1.0" friction="0.0001"/>
		<origin rpy="0.00000 -0.00000 0.00000" xyz="0.38000 -0.32000 0.00000"/>
		<axis xyz="0.00000 0.00000 1.00000"/>
	</joint>
	<joint name="jointfix_23_39" type="fixed">
		<parent link="link0_39"/>
		<child link="hingerightdoor"/>
		<dynamics damping="1.0" friction="0.0001"/>
		<origin rpy="0.00000 -0.00000 0.00000" xyz="0.00000 0.00000 0.00000"/>
		<axis xyz="0.00000 0.00000 0.00000"/>
	</joint>
	<joint name="jointfix_28_0" type="fixed">
		<parent link="desk"/>
		<child link="microwave"/>
		<dynamics damping="1.0" friction="0.0001"/>
		<origin rpy="0.00000 -0.00000 0.00000" xyz="-0.75000 -0.02500 1.60000"/>
		<axis xyz="0.00000 0.00000 0.00000"/>
	</joint>
	<joint name="jointfix_27_40" type="fixed">
		<parent link="microwave"/>
		<child link="microroot"/>
		<dynamics damping="1.0" friction="0.0001"/>
		<origin rpy="0.00000 -0.00000 0.00000" xyz="0.00000 0.00000 0.00000"/>
		<axis xyz="0.00000 0.00000 0.00000"/>
	</joint>
	<joint name="microwave" type="revolute">
		<parent link="microroot"/>
		<child link="link0_43"/>
		<limit effort="0.00000" lower="-2.09400" upper="0.00000" velocity="0.00000"/>
		<dynamics damping="1.0" friction="0.0001"/>
		<origin rpy="0.00000 -0.00000 0.00000" xyz="-0.34500 -0.17600 0.19200"/>
		<axis xyz="0.00000 0.00000 1.00000"/>
	</joint>
	<joint name="jointfix_26_43" type="fixed">
		<parent link="link0_43"/>
		<child link="microdoorroot"/>
		<dynamics damping="1.0" friction="0.0001"/>
		<origin rpy="0.00000 -0.00000 0.00000" xyz="0.00000 0.00000 0.00000"/>
		<axis xyz="0.00000 0.00000 0.00000"/>
	</joint>
</robot>
