<!--Copyright 2020 Google LLC-->

<!--Licensed under the Apache License, Version 2.0 (the "License");-->
<!--you may not use this file except in compliance with the License.-->
<!--You may obtain a copy of the License at-->

    <!--https://www.apache.org/licenses/LICENSE-2.0-->

<!--Unless required by applicable law or agreed to in writing, software-->
<!--distributed under the License is distributed on an "AS IS" BASIS,-->
<!--WITHOUT WARRANTIES OR CONDITIONS OF ANY KIND, either express or implied.-->
<!--See the License for the specific language governing permissions and-->
<!--limitations under the License.-->

<mujoco model="franka_kitchen">

    <size njmax='1000' nconmax='1000'/>

    <!-- <include file="basic_scene.xml"/> -->
    <!-- <include file="../franka_assets/franka_assets.xml"/> -->
    <!-- <include file="item_assets/oven_asset.xml"/> -->
    <compiler inertiafromgeom="auto" inertiagrouprange="4 4" angle="radian"/>
    <asset>
        <mesh file="hood.stl" name="hood"/>
        <mesh file="lightswitch.stl" name="lightswitch"/>
        <mesh file="lightswitchbase.stl" name="lightswitchbase"/>
        <mesh file="knob.stl" name="knob"/>
        <mesh file="stoverim.stl" name="stoverim"/>
        <mesh file="burnerplate.stl" name="burnerplate"/>
        <mesh file="ovenhandle.stl" name="ovenhandle"/>
        <mesh file="oven.stl" name="oven"/>
        <mesh file="oventop.stl" name="oventop"/>
        <mesh file="ovenwindow.stl" name="ovenwindow"/>
        <texture name="T_oven_wood" type="cube" height="1" width="1" file="wood1.png"/>
        <texture name="T_oven_metal" type="cube" height="1" width="1" file="metal1.png"/>
        <material name="oven_wood" texture="T_oven_wood" texrepeat="3 3" reflectance="0.7" shininess=".4" texuniform="false"/>
        <material name="oven_metal" rgba="1 1 1 1" texture="T_oven_metal" texrepeat="3 3" reflectance="1" shininess="1" texuniform="false"/>
        <material name="oven_black" rgba=".15 .15 .15 1" reflectance=".2" shininess=".2" />
        <material name="oven_burner" rgba="2 0 0 1" reflectance=".2" shininess=".2" />
        <material name="oven_block" rgba=".1 .1 .1 1"/>
        <material name="oven_collision_blue" rgba="0.3 0.3 1.0 0.5" shininess="0" specular="0"/>
    </asset>
    <default>
        <default class="oven">
            <joint armature="0.001" damping="2" limited="true"/>
            <geom conaffinity="0" contype="0" group="1" material="oven_metal" type="mesh"/>
            <default class="ovenlight" >
                <light directional="false" castshadow="true" attenuation="0.03 0.03 0.03" cutoff="100" exponent="25" diffuse=".7 .65 .65" specular=".3 .3 .3"/>
            </default>
            <default class="oven_collision">
                <geom conaffinity="1" condim="3" contype="0" group="4" margin="0.001" material="oven_collision_blue" type="mesh"/>
            </default>
        </default>
    </default>
    <equality>
        <joint polycoef="0 174 0 0 0" joint1="knob_Joint_1" joint2="bottom_right_burner"/>
        <joint polycoef="0 174 0 0 0" joint1="knob_Joint_2" joint2="bottom_left_burner"/>
        <joint polycoef="0 174 0 0 0" joint1="knob_Joint_3" joint2="top_right_burner"/>
        <joint polycoef="0 174 0 0 0" joint1="knob_Joint_4" joint2="top_left_burner"/>
        <joint polycoef="0 14 0 0 0" joint1="light_switch" joint2="light_joint"/>
    </equality>

    <!-- <include file="item_assets/counters_asset.xml"/> -->
    <compiler inertiafromgeom="auto" inertiagrouprange="4 4" angle="radian"/>
    <asset>
        <mesh file="cabinetdrawer.stl" name="cabinetdrawer"/>
        <mesh file="cabinethandle.stl" name="cabinethandle"/>
        <mesh file="cabinetbase.stl" name="cabinetbase"/>
        <mesh file="countertop.stl" name="countertop"/>
        <mesh file="faucet.stl" name="faucet"/>
        <texture name="T_counter_metal" type="cube" height="1" width="1" file="metal1.png" />
        <texture name="T_counter_marble" type="cube" height="1" width="1" file="marble1.png" />
        <material name="counter_metal" rgba="1 1 1 1" texture="T_counter_metal" texrepeat="3 3" reflectance=".5" shininess="1" texuniform="false" />
        <material name="counter_marble"  texture="T_counter_marble" texrepeat="1 1" reflectance=".2" shininess="1" texuniform="false" />
        <material name="counter_black" rgba=".2 .2 .2 1" reflectance="1" shininess="1"  />
        <material name="counter_blue" rgba=".46 .5 .6 1" reflectance="1" shininess="1"  />
        <material name="counter_collision_blue" rgba="0.3 0.3 1.0 0.5" shininess="0" specular="0" />
    </asset>
    <default>
        <default class="counters">
            <joint damping="2" frictionloss="2" armature=".01" limited="true"/>
            <geom conaffinity="0" contype="0" group="1" material="counter_metal" type="mesh"/>
            <default class="counter_collision">
                <geom conaffinity="1" condim="3" contype="0" group="4" margin="0.001" material="counter_collision_blue"/>
            </default>
        </default>
    </default>

    <!-- <include file="item_assets/backwall_asset.xml"/> -->
    <compiler inertiafromgeom="auto" inertiagrouprange="4 4" angle="radian"/>
    <asset>
        <texture name="T_wall_marble" type="cube" height="1" width="1" file="marble1.png"/>
        <texture name="T_wall_metal" type="cube" height="1" width="1" file="metal1.png"/>
        <material name="wall_white" rgba="1 1 1 1" reflectance="0" shininess="0"/>
        <material name="wall_blue" rgba=".66 .7 .8 1" reflectance="0" shininess="0"/>
        <material name="wall_collision_blue" rgba="0.3 0.3 1.0 0.5" shininess="0" specular="0"/>
    </asset>
    <default>
        <default class="backwall">
            <geom conaffinity="0" contype="0" group="1" material="wall_blue"/>
            <default class="wall_collision">
                <geom conaffinity="1" condim="3" contype="0" group="4" margin="0.001" material="wall_collision_blue"/>
            </default>
        </default>
    </default>

    <!-- <include file="item_assets/slidecabinet_asset.xml"/> -->
    <compiler inertiafromgeom="auto" inertiagrouprange="4 4" angle="radian"/>
    <asset>
        <texture name="T_slide_metal" type="cube" height="1" width="1" file="metal1.png"/>
        <material name="M_slide_metal" texture="T_slide_metal" texrepeat="3 3" reflectance="0.7" shininess=".4" texuniform="false"/>
        <material name="M_slide_blue" rgba=".46 .5 .6 1" reflectance="0.7" shininess=".4"/>
        <material name="slide_collision_blue" rgba="0.3 0.3 1.0 0.5" shininess="0" specular="0"/>
    </asset>
    <default>
        <default class="slidecabinet">
            <joint damping="2" frictionloss="2" armature=".01" limited="true"/>
            <geom conaffinity="0" contype="0" group="1" material="M_slide_blue" type="mesh"/>
            <default class="slide_collision">
                <geom conaffinity="1" condim="3" contype="0" group="4" margin="0.001" material="slide_collision_blue"/>
            </default>
        </default>
    </default>

    <!-- <include file="item_assets/hingecabinet_asset.xml"/> -->
    <compiler inertiafromgeom="auto" inertiagrouprange="4 4" angle="radian"/>
    <asset>
        <texture name="T_hinge_wood" type="cube" height="1" width="1" file="wood1.png"/>
        <texture name="T_hinge_metal" type="cube" height="1" width="1" file="metal1.png"/>
        <material name="M_hinge_wood" texture="T_hinge_wood" texrepeat="3 3" reflectance="0.7" shininess=".4" texuniform="false"/>
        <material name="M_hinge_metal" texture="T_hinge_metal" texrepeat="3 3" reflectance="0.7" shininess=".4" texuniform="false"/>
        <material name="M_hinge_blue" rgba=".46 .5 .6 1" reflectance="0.7" shininess=".4"/>
        <material name="hinge_collision_blue" rgba="0.3 0.3 1.0 0.5" shininess="0" specular="0"/>
    </asset>
    <default>
        <default class="hingecabinet">
            <joint damping="2" frictionloss="2" armature=".01" limited="true"/>
            <geom conaffinity="0" contype="0" group="1" material="M_hinge_wood" type="mesh"/>
            <default class="hinge_collision">
                <geom conaffinity="1" condim="3" contype="0" group="4" margin="0.001" material="hinge_collision_blue" solimp=".8 .9 .01" solref=".02 1"/>
            </default>
        </default>
    </default>

    <!-- <include file="item_assets/microwave_asset.xml"/> -->
    <compiler inertiafromgeom="auto" inertiagrouprange="4 4" angle="radian"/>
    <asset>
        <mesh file="micro.stl" name="micro"/>
        <mesh file="microdoor.stl" name="microdoor"/>
        <mesh file="microbutton.stl" name="microbutton"/>
        <mesh file="microfeet.stl" name="microfeet"/>
        <mesh file="microhandle.stl" name="microhandle"/>
        <mesh file="microwindow.stl" name="microwindow"/>
        <texture name="T_micro_metal" type="cube" height="1" width="1" file="metal1.png"/>
        <material name="micro_metal" rgba="1 1 1 1" texture="T_micro_metal" texrepeat="3 3" reflectance="1" shininess="1" texuniform="false"/>
        <material name="micro_black" rgba=".2 .2 .2 1" reflectance="1" shininess="1"/>
        <material name="micro_window" rgba=".4 .4 .4 .25" reflectance="1" shininess="1"/>
        <material name="micro_collision_blue" rgba="0.3 0.3 1.0 0.5" shininess="0" specular="0"/>
    </asset>
    <default>
        <default class="microwave">
            <joint damping="2" frictionloss="2" armature=".01" limited="true"/>
            <geom conaffinity="0" contype="0" group="1" material="micro_black" type="mesh"/>
            <default class="micro_collision">
                <geom conaffinity="1" condim="3" contype="0" group="4" margin="0.001" material="micro_collision_blue" solimp=".8 .9 .01" solref=".02 1"/>
            </default>
        </default>
    </default>

    <!-- <include file="item_assets/kettle_asset.xml"/> -->
    <compiler inertiafromgeom="auto" inertiagrouprange="4 4" angle="radian"/>
    <asset>
        <mesh file="kettle.stl" name="kettle"/>
        <mesh file="kettlehandle.stl" name="kettlehandle"/>
        <texture name="T_kettle_metal" type="cube" height="1" width="1" file="metal1.png" />
        <texture name="T_kettle_wood" type="cube" height="1" width="1" file="wood1.png" />
        <material name="kettle_wood" rgba="1 1 1 1" texture="T_kettle_wood" texrepeat="3 3" reflectance="1" shininess="1" texuniform="false" />
        <material name="kettle_metal" rgba="1 1 1 1" texture="T_kettle_metal" texrepeat="3 3" reflectance="1" shininess="1" texuniform="false" />
        <material name="kettle_white" rgba=".9 .9 .9 1" reflectance="1" shininess="1" />
        <material name="kettle_collision_blue" rgba="0.3 0.3 1.0 0.5" shininess="0" specular="0" />
    </asset>
    <default class="kettle">
        <joint damping="2" frictionloss="2" armature=".01" limited="true" />
        <geom conaffinity="0" contype="0" group="1" material="kettle_white" type="mesh"/>
        <default class="kettle_collision">
            <geom conaffinity="1" condim="4" contype="1" group="4" margin="0.001" material="kettle_collision_blue" solimp=".8 .9 .01" solref=".02 1" type="mesh"/>
        </default>
    </default>

    <visual>
    <global offwidth="2560" offheight="1920" />
    <quality shadowsize="4096" offsamples="8" />
    <map force="0.1" fogend="5" />
    </visual>

    <compiler inertiafromgeom='auto' inertiagrouprange='3 5' angle="radian" texturedir="./textures/" meshdir="./meshes/"/>
    <worldbody>
        <!-- <camera name='left_cap' pos='-1.2 -0.5 1.8' quat='0.78 0.49 -0.22 -0.32' /> -->
        <!-- <camera name='right_cap' pos='1.2 -0.5 1.8' quat='0.76 0.5 0.21 0.35'/> -->

        <!-- Robot -->
        <!-- <body pos='0. 0 1.8' euler='0 0 1.57'> -->
            <!-- <geom type='cylinder' size='.120 .90' pos='-.04 0 -0.90'/> -->
            <!-- <include file="../franka_assets/chain.xml"/> -->
        <!-- </body> -->

        <body name='desk' pos='-0.1 0.75 0'>
            <body name="counters1" pos="0 0 0" >
                <!-- <include file="item_assets/counters_chain.xml"/> -->
                <body name="counters" childclass="counters">
                    <geom material="counter_blue" mesh="cabinetbase" type="mesh"/>
                    <geom material="counter_marble" mesh="countertop" type="mesh"/>
                    <geom material="counter_marble" pos="-0.855 -0.508 1.57" size="0.463 1.08 0.03" type="box"/>
                    <geom mesh="faucet" pos="0.904 -0.172 1.511" type="mesh"/>
                    <geom pos="0.9 0.085 1.83" size="0.035 0.05" type="cylinder"/>
                    <geom pos="0.9 0.085 1.92" size="0.025 0.08" type="capsule"/>
                    <geom euler="1.57 0 0" pos="0.9 0.2 2" size="0.025 0.11" type="capsule"/>
                    <geom pos="0.9 0.317 1.8" size="0.025 0.2" type="capsule"/>
                    <geom pos="0.9 0.317 1.67" size="0.032 0.07" type="cylinder"/>
                    <geom pos="0.947 0.318 1.68" euler="0 1.57 0" size="0.029 0.03" type="cylinder"/>
                    <geom pos="0.99 0.318 1.68" euler="0 1.57 0" size="0.035 0.013 " type="cylinder"/>
                    <geom euler="1.57 0 0" pos="0.99 0.26 1.68" size="0.01 0.03" type="capsule"/>
                    <geom euler="0 1.57 0" pos="0.909 -0.695 1.39" size="0.022 0.28" type="cylinder"/>
                    <geom euler="1.57 0 0" pos="0.71 -0.665 1.39" size="0.018 0.03" type="cylinder"/>
                    <geom euler="1.57 0 0" pos="1.108 -0.665 1.39" size="0.018 0.03" type="cylinder"/>
                    <geom euler="0 1.57 0" pos="0.909 -0.695 1.14" size="0.022 0.28" type="cylinder"/>
                    <geom euler="1.57 0 0" pos="0.71 -0.665 1.14" size="0.018 0.03" type="cylinder"/>
                    <geom euler="1.57 0 0" pos="1.108 -0.665 1.14" size="0.018 0.03" type="cylinder"/>
                    <geom class="counter_collision" euler="0 1.57 0" pos="0.909 -0.695 1.39" size="0.022 0.28" type="cylinder" mass=".1"/>
                    <geom class="counter_collision" euler="1.57 0 0" pos="0.71 -0.665 1.39" size="0.018 0.03" type="cylinder" mass=".02"/>
                    <geom class="counter_collision" euler="1.57 0 0" pos="1.108 -0.665 1.39" size="0.018 0.03" type="cylinder" mass=".02"/>
                    <geom class="counter_collision" euler="0 1.57 0" pos="0.909 -0.695 1.14" size="0.022 0.28" type="cylinder" mass=".1"/>
                    <geom class="counter_collision" euler="1.57 0 0" pos="0.71 -0.665 1.14" size="0.018 0.03" type="cylinder" mass=".02"/>
                    <geom class="counter_collision" euler="1.57 0 0" pos="1.108 -0.665 1.14" size="0.018 0.03" type="cylinder" mass=".02"/>
                    <geom class="counter_collision" pos="-0.86 -0.5 0.78" size="0.46 1.07 0.777" type="box" mass="5"/>
                    <geom class="counter_collision" pos="0.907 -0.045 0.71" size="0.304 0.606 0.71" type="box" mass="3"/>
                    <geom class="counter_collision" pos="-0.855 -0.508 1.57" size="0.463 1.08 0.03" type="box" mass=".5"/>
                    <geom class="counter_collision" pos="1.159 -0.045 1.57" size="0.051 0.611 0.03" type="box" mass=".2"/>
                    <geom class="counter_collision" pos="0.649 -0.045 1.57" size="0.051 0.611 0.03" type="box" mass=".2"/>
                    <geom class="counter_collision" pos="0.904 0.4 1.57" size="0.204 0.165 0.03" type="box" mass=".2"/>
                    <geom class="counter_collision" pos="0.904 -0.617 1.57" size="0.204 0.039 0.03" type="box" mass=".2"/>
                    <geom class="counter_collision" pos="1.158 -0.04 1.47" size="0.05 0.61 0.076" type="box" mass=".2"/>
                    <geom class="counter_collision" pos="0.652 -0.04 1.47" size="0.05 0.61 0.076" type="box" mass=".2"/>
                    <geom class="counter_collision" pos="0.904 0.401 1.47" size="0.204 0.166 0.076" type="box" mass=".2"/>
                    <geom class="counter_collision" pos="0.904 -0.611 1.47" size="0.206 0.034 0.076" type="box" mass=".2"/>
                    <geom class="counter_collision" pos="0.9 0.085 1.83" size="0.035 0.05" type="cylinder" mass=".02"/>
                    <geom class="counter_collision" pos="0.9 0.085 1.92" size="0.025 0.08" type="capsule" mass=".02"/>
                    <geom class="counter_collision" euler="1.57 0 0" pos="0.9 0.2 2" size="0.025 0.11" type="capsule" mass=".02"/>
                    <geom class="counter_collision" pos="0.9 0.317 1.8" size="0.025 0.2" type="capsule" mass=".02"/>
                    <geom class="counter_collision" pos="0.9 0.317 1.67" size="0.032 0.07" type="cylinder" mass=".02"/>
                    <geom class="counter_collision" pos="0.947 0.318 1.68" euler="0 1.57 0" size="0.029 0.03" type="cylinder" mass=".02"/>
                    <geom class="counter_collision" pos="0.99 0.318 1.68" euler="0 1.57 0" size="0.035 0.013 " type="cylinder" mass=".02"/>
                    <geom class="counter_collision" euler="1.57 0 0" pos="0.99 0.26 1.68" size="0.01 0.03" type="capsule" mass=".02"/>
                </body>
            </body>
            <body name="oven" pos="0 0 0" >
                <!-- <include file="item_assets/oven_chain.xml"/> -->
                <!-- <light class="ovenlight" name="ovenlight" pos="0 .2 2.25" dir="0 -.02 -.1" attenuation="0.05 0.05 0.05" cutoff="75" diffuse=".7 .65 .65" specular=".3 .3 .3"/> -->
                <body name="ovenroot" childclass="oven" pos="0.115 -0.2921 0.9834">
                    <geom material="oven_black" mesh="burnerplate" pos="-0.24 -0.119 0.629" type="mesh"/>
                    <geom material="oven_black" mesh="burnerplate" pos="-0.237 0.322 0.629" type="mesh"/>
                    <geom material="oven_black" mesh="burnerplate" pos="0.204 0.322 0.629" type="mesh"/>
                    <geom material="oven_black" mesh="burnerplate" pos="0.206 -0.119 0.629" type="mesh"/>
                    <geom material="oven_black" euler="1.57 0 0" pos="-.215 -0.36 -0.682" size="0.018 0.03" type="cylinder"/>
                    <geom material="oven_black" euler="1.57 0 0" pos=".184 -0.36 -0.682" size="0.018 0.03" type="cylinder"/>
                    <geom material="oven_black" euler="0 1.57 0" pos="-0.015 -0.39 -0.682" size="0.022 0.28" type="cylinder"/>
                    <geom material="oven_black" euler="1.57 0 0" pos="-.215 -0.36 0.254" size="0.018 0.03" type="cylinder"/>
                    <geom material="oven_black" euler="1.57 0 0" pos=".184 -0.36 0.254" size="0.018 0.03" type="cylinder"/>
                    <geom material="oven_black" euler="0 1.57 0" pos="-0.015 -0.39 0.254" size="0.022 0.28" type="cylinder"/>
                    <geom material="oven_black" mesh="oventop" pos="-0.017 0.275 0.607" type="mesh"/>
                    <geom material="oven_black" mesh="ovenwindow" pos="0.9793 0.2921 -1.1877" type="mesh"/>
                    <geom material="oven_black" pos="-0.011 -.327 -.05" size="0.35 0.016 0.22" type="box"/>
                    <geom mesh="stoverim" pos="0.203 0.323 0.619" type="mesh"/>
                    <geom mesh="stoverim" pos="-0.24 -0.12 0.619" type="mesh"/>
                    <geom mesh="stoverim" pos="-0.237 0.323 0.619" type="mesh"/>
                    <geom mesh="stoverim" pos="0.207 -0.12 0.619" type="mesh"/>
                    <geom pos="-0.017 -.326 .455" size="0.5 0.016 0.12" type="box"/>
                    <geom pos="-0.017 -.326 -.795" size="0.5 0.016 0.185" type="box"/>
                    <geom pos="-0.017 -.326 -.14" size="0.5 0.016 0.465" type="box"/>
                    <geom pos="-0.017 0.295 -0.2" size="0.5 0.602 0.78" type="box"/>
                    <geom class="oven_collision" pos="-0.017 0.28 -0.175" size="0.5 0.625 0.81" type="box" mass="5"/>
                    <geom class="oven_collision" euler="1.57 0 0" pos="-.215 -0.36 -0.682" size="0.018 0.03" type="cylinder" mass=".2"/>
                    <geom class="oven_collision" euler="1.57 0 0" pos=".184 -0.36 -0.682" size="0.018 0.03" type="cylinder" mass=".2"/>
                    <geom class="oven_collision" euler="0 1.57 0" pos="-0.015 -0.39 -0.682" size="0.022 0.28" type="cylinder" mass=".2"/>
                    <geom class="oven_collision" euler="1.57 0 0" pos="-.215 -0.36 0.254" size="0.018 0.03" type="cylinder" mass=".2"/>
                    <geom class="oven_collision" euler="1.57 0 0" pos=".184 -0.36 0.254" size="0.018 0.03" type="cylinder" mass=".2"/>
                    <geom class="oven_collision" euler="0 1.57 0" pos="-0.015 -0.39 0.254" size="0.022 0.28" type="cylinder" mass=".2"/>
                    <body name="knob 1" euler="1.57 0 0" pos="-0.148 0.22 1.243">
                        <joint name="knob_Joint_1" axis="0 0 1" type="hinge" limited="true" range="-1.57 0"/>
                        <geom type="box" pos="0 0 .038" size=".014 .048 .018"/>
                        <geom type="cylinder" pos="0 0 .013" size=".05 .008"/>
                        <geom type="cylinder" pos="0 0.048 .037" size=".014 .018" rgba="1 0 0 1"/>
                        <geom class="oven_collision" type="box" pos="0 0 .038" size=".014 .048 .018" mass=".01"/>
                        <geom class="oven_collision" type="cylinder" pos="0 0 .013" size=".05 .008" mass=".01"/>
                        <site type="sphere" name="knob1_site" pos="0 0 .038" size=".01" group="3" rgba="1 1 0 1"/>
                    </body>
                    <body name="Burner 1" pos="0.206 -0.119 0.61">
                        <inertial pos="0 0 0" mass=".01" diaginertia="0.001 0.001 0.001"/>
                        <joint name="bottom_right_burner" axis="0 0 -1" type="slide" limited="true" range="-.009 0"/>
                        <geom material="oven_burner" size="0.1 0.01" type="cylinder"/>
                    </body>
                    <body name="knob 2" euler="1.57 0 0" pos="-0.271 0.22 1.243">
                        <joint name="knob_Joint_2" axis="0 0 1" type="hinge" limited="true" range="-1.57 0"/>
                        <geom type="box" pos="0 0 .038" size=".014 .048 .018"/>
                        <geom type="cylinder" pos="0 0 .013" size=".05 .008"/>
                        <geom type="cylinder" pos="0 0.048 .037" size=".014 .018" rgba="1 0 0 1"/>
                        <geom class="oven_collision" type="box" pos="0 0 .038" size=".014 .048 .018" mass=".01"/>
                        <geom class="oven_collision" type="cylinder" pos="0 0 .013" size=".05 .008" mass=".01"/>
                        <site type="sphere" name="knob2_site" pos="0 0 .038" size=".01" group="3" rgba="0 0 1 1"/>
                    </body>
                    <body name="Burner 2" pos="-0.24 -0.119 0.61">
                        <inertial pos="0 0 0" mass=".01" diaginertia="0.001 0.001 0.001"/>
                        <joint name="bottom_left_burner" axis="0 0 -1" type="slide" limited="true" stiffness="1" range="-.009 0"/>
                        <geom material="oven_burner" size="0.1 0.01" type="cylinder" group="1"/>
                    </body>
                    <body name="knob 3" euler="1.57 0 0" pos="-0.148 0.22 1.357">
                        <joint name="knob_Joint_3" axis="0 0 1" type="hinge" limited="true" range="-1.57 0"/>
                        <geom type="box" pos="0 0 .038" size=".014 .048 .018"/>
                        <geom type="cylinder" pos="0 0 .013" size=".05 .008"/>
                        <geom type="cylinder" pos="0 0.048 .037" size=".014 .018" rgba="1 0 0 1"/>
                        <geom class="oven_collision" type="box" pos="0 0 .038" size=".014 .048 .018" mass=".01"/>
                        <geom class="oven_collision" type="cylinder" pos="0 0 .013" size=".05 .008" mass=".01"/>
                        <site type="sphere" name="knob3_site" pos="0 0 .038" size=".01" group="3" rgba="0 1 0 1"/>
                    </body>
                    <body name="Burner 3" pos="0.204 0.322 0.61">
                        <inertial pos="0 0 0" mass=".01" diaginertia="0.001 0.001 0.001"/>
                        <joint name="top_right_burner" axis="0 0 -1" type="slide" limited="true" stiffness="1" range="-.009 0"/>
                        <geom material="oven_burner" size="0.1 0.01" type="cylinder" group="1"/>
                    </body>
                    <body name="knob 4" euler="1.57 0 0" pos="-0.271 0.22 1.357">
                        <joint name="knob_Joint_4" axis="0 0 1" type="hinge" limited="true" range="-1.57 0"/>
                        <geom type="box" pos="0 0 .038" size=".014 .048 .018"/>
                        <geom type="cylinder" pos="0 0 .013" size=".05 .008"/>
                        <geom type="cylinder" pos="0 0.048 .037" size=".014 .018" rgba="1 0 0 1"/>
                        <geom class="oven_collision" type="box" pos="0 0 .038" size=".014 .048 .018" mass=".01"/>
                        <geom class="oven_collision" type="cylinder" pos="0 0 .013" size=".05 .008" mass=".01"/>
                        <site type="sphere" name="knob4_site" pos="0 0 .038" size=".01" group="3" rgba="1 0 0 1"/>
                    </body>
                    <body name="Burner 4" pos="-0.237 0.322 0.61">
                        <inertial pos="0 0 0" mass=".01" diaginertia="0.001 0.001 0.001"/>
                        <joint name="top_left_burner" axis="0 0 -1" type="slide" limited="true" stiffness="1" range="-.009 0"/>
                        <geom material="oven_burner" size="0.1 0.01" type="cylinder" group="1"/>
                    </body>
                </body>
                <body name="hoodroot" pos="0.1 0.188 2.33" childclass="oven">
                    <geom material="oven_black" mesh="hood" pos="-0.1 -0.2896 -2.329" type="mesh"/>
                    <geom class="oven_collision" pos="0 0.073 -0.046" size="0.502 0.336 0.12" type="box" mass="2"/>
                    <body name="lightswitchbaseroot" pos="-0.4 -0.2473 -0.05" >
                        <geom mesh="lightswitchbase" pos="0 -0.0123 0" euler="-1.57 0 0" type="mesh"/>
                        <body name="lightswitchroot">
                            <inertial pos="-0.0046 0.35 0.0131" mass=".1" diaginertia="0.001 0.001 0.001"/>
                            <joint axis="0 0 1" limited="true" name="light_switch" frictionloss="1" range="-.7 0" type="hinge"/>
                            <geom pos="0.0252 -0.06 0" euler="-1.57 -.4 0" size="0.02 0.035" type="capsule"/>
                            <geom class="oven_collision" euler="-1.57 -.4 0" pos="0.0263 -0.065 0" size="0.021 0.03" type="capsule" mass=".01"/>
                            <site type="sphere" name="light_site" pos="0.0315 -0.075 0" size=".01" group="3" rgba="1 0 0 1"/>
                        </body>
                    </body>
                    <body name="lightblock_hinge" pos="-0.0044 -0.3 -0.1361">
                        <inertial pos="-0.0046 0.35 0.0131" mass=".01" diaginertia="0.001 0.001 0.001"/>
                        <joint axis="0 0 -1" type="slide" limited="true" name="light_joint" frictionloss="1" range="-.05 0"/>
                        <geom material="oven_block" pos="-0.008 0.4 -0.01" size="0.4 0.3 0.015" type="box"/>
                    </body>
                </body>
            </body>
            <body name="backwall" pos="0 0 0" >
                <!-- <include file="item_assets/backwall_chain.xml"/> -->
                <body name="wallroot" childclass="backwall" pos="0.059 0.584 1.587">
                    <geom pos="-.11 0.06 .6" size="1.26 0.07 0.6" type="box"/>
                    <geom material="wall_white" pos="-0.11 0.06 0.145" size="1.26 0.08 0.145" type="box"/>
                    <geom class="wall_collision" pos="-.11 0.06 .6" size="1.26 0.07 0.6" type="box" mass=".2"/>
                    <geom class="wall_collision" pos="-0.11 0.06 0.145" size="1.26 0.08 0.145" type="box" mass=".2"/>
                </body>
                <body euler="0 0 1.57" name="wall2" childclass="backwall" pos="-1.305 -0.546 1.587">
                    <geom pos="0.044 .06 0.6" size="1.079 0.07 0.6" type="box"/>
                    <geom material="wall_white" pos="0.044 .06 0.145" size="1.079 0.08 0.145" type="box"/>
                    <geom class="wall_collision" pos="0.044 .06 0.6" size="1.079 0.07 0.6" type="box" mass=".2"/>
                    <geom class="wall_collision" pos="0.044 .06 0.145" size="1.079 0.08 0.145" type="box" mass=".2"/>
                </body>
            </body>
            <body name="slidecabinet" pos="0.4 0.3 2.6" >
                <!-- <include file="item_assets/slidecabinet_chain.xml"/> -->
                <body name="slide" childclass="slidecabinet">
                    <geom pos="-0.225 0 -0.18" size="0.223 0.3 0.02" type="box"/>
                    <geom pos="0.224 0 0" size="0.226 0.3 0.2" type="box"/>
                    <geom pos="-0.225 0 0.18" size="0.223 0.3 0.02" type="box"/>
                    <geom pos="-0.426 0 0" size="0.022 0.3 0.16" type="box"/>
                    <geom pos="-0.2 0.276 0.0" size="0.21 0.024 0.16" type="box"/>
                    <geom class="slide_collision" pos="-0.225 0 -0.18" size="0.223 0.3 0.02" type="box" mass=".2"/>
                    <geom class="slide_collision" pos="0.224 0 0" size="0.226 0.3 0.2" type="box" mass="1"/>
                    <geom class="slide_collision" pos="-0.225 0 0.18" size="0.223 0.3 0.02" type="box" mass=".2"/>
                    <geom class="slide_collision" pos="-0.426 0 0" size="0.022 0.3 0.16" type="box" mass=".2"/>
                    <geom class="slide_collision" pos="-0.2 0.276 0" size="0.2 0.024 0.16" type="box" mass=".2"/>
                    <body name="slidelink" pos="-0.225 -0.32 0">
                        <joint name="slide_cabinet" axis="1 0 0" type="slide" range="0 .44"/>
                        <geom material="M_slide_metal" euler="1.57 0 0" pos="-0.183 -0.06 -0.114" size="0.019 0.053 0.019" type="cylinder"/>
                        <geom material="M_slide_metal" euler="1.57 0 0" pos="-0.183 -0.06 0.114" size="0.019 0.053 0.019" type="cylinder"/>
                        <geom material="M_slide_metal" pos="-0.183 -0.123 0" size="0.022 0.159" type="cylinder"/>
                        <geom pos="0 -.02 0" size="0.225 0.03 0.195" type="box"/>
                        <geom class="slide_collision" pos="0 -.02 0" size="0.225 0.03 0.195" type="box" mass=".2"/>
                        <geom class="slide_collision" euler="1.57 0 0" pos="-0.183 -0.06 -0.114" size="0.019 0.053 0.019" type="cylinder" mass=".02"/>
                        <geom class="slide_collision" euler="1.57 0 0" pos="-0.183 -0.06 0.114" size="0.019 0.053 0.019" type="cylinder" mass=".02"/>
                        <geom class="slide_collision" pos="-0.183 -0.123 0" size="0.022 0.159" type="cylinder" mass=".1"/>
                        <site type="sphere" name="slide_site" pos="-0.183 -0.123 0" size=".01" group="3"/>
                    </body>
                </body>
            </body>
            <body name="hingecabinet" pos="-0.504 0.28 2.6" >
                <!-- <include file="item_assets/hingecabinet_chain.xml"/> -->
                <body name="hingecab" childclass="hingecabinet">
                    <geom material="M_hinge_blue" size="0.04 0.3 0.2" type="box"/>
                    <geom material="M_hinge_blue" pos="0.38 0 0" size="0.02 0.3 0.2" type="box"/>
                    <geom material="M_hinge_blue" pos="-0.38 0 0" size="0.02 0.3 0.2" type="box"/>
                    <geom material="M_hinge_blue" pos="-0.2 0 0.18" size="0.16 0.3 0.02" type="box"/>
                    <geom material="M_hinge_blue" pos="-0.2 0 -0.18" size="0.16 0.3 0.02" type="box"/>
                    <geom material="M_hinge_blue" pos="0.2 0 -0.18" size="0.16 0.3 0.02" type="box"/>
                    <geom material="M_hinge_blue" pos="0.2 0 0.18" size="0.16 0.3 0.02" type="box"/>
                    <geom material="M_hinge_blue" pos="-0.2 0.28 0" size="0.16 0.02 0.16" type="box"/>
                    <geom material="M_hinge_blue" pos="0.2 0.28 0" size="0.16 0.02 0.16" type="box"/>
                    <geom class="hinge_collision" size="0.04 0.3 0.2" type="box" mass=".3"/>
                    <geom class="hinge_collision" pos="0.38 0 0" size="0.02 0.3 0.2" type="box" mass=".2"/>
                    <geom class="hinge_collision" pos="-0.38 0 0" size="0.02 0.3 0.2" type="box" mass=".2"/>
                    <geom class="hinge_collision" pos="-0.2 0 0.18" size="0.16 0.3 0.02" type="box" mass=".2"/>
                    <geom class="hinge_collision" pos="-0.2 0 -0.18" size="0.16 0.3 0.02" type="box" mass=".2"/>
                    <geom class="hinge_collision" pos="0.2 0 -0.18" size="0.16 0.3 0.02" type="box" mass=".2"/>
                    <geom class="hinge_collision" pos="0.2 0 0.18" size="0.16 0.3 0.02" type="box" mass=".2"/>
                    <geom class="hinge_collision" pos="-0.2 0.28 0" size="0.16 0.02 0.16" type="box" mass=".2"/>
                    <geom class="hinge_collision" pos="0.2 0.28 0" size="0.16 0.02 0.16" type="box" mass=".2"/>
                    <body name="hingeleftdoor" pos="-0.38 -0.32 0">
                        <joint axis="0 0 1" name="left_hinge_cabinet" range="-1.57 0" type="hinge"/>
                        <geom material="M_hinge_metal" pos="0.302 -0.128 0" size="0.022 0.16" type="cylinder"/>
                        <geom material="M_hinge_metal" pos="0.302 -0.061 0.114" euler="1.57 0 0" size="0.019 0.053 0.02" type="cylinder"/>
                        <geom material="M_hinge_metal" pos="0.302 -0.061 -0.114" euler="1.57 0 0" size="0.019 0.053 0.02" type="cylinder"/>
                        <geom material="M_hinge_blue" pos="0.184 -.015 0" size="0.193 0.03 0.2" type="box"/>
                        <geom class="hinge_collision" pos="0.184 -.015 0" size="0.193 0.03 0.2" type="box" mass=".2"/>
                        <geom class="hinge_collision" pos="0.302 -0.128 0" size="0.022 0.16" type="cylinder" mass=".1"/>
                        <geom class="hinge_collision" pos="0.302 -0.061 0.114" euler="1.57 0 0" size="0.019 0.053 0.02" type="cylinder" mass=".02"/>
                        <geom class="hinge_collision" pos="0.302 -0.061 -0.114" euler="1.57 0 0" size="0.019 0.053 0.02" type="cylinder" mass=".02"/>
                        <site type="sphere" name="hinge_site1" pos="0.302 -0.128 0" size=".01" group="3" rgba="1 0 0 1"/>
                    </body>
                    <body name="hingerightdoor" pos="0.38 -0.32 0">
                        <joint axis="0 0 1" name="right_hinge_cabinet" range="0 1.57" type="hinge"/>
                        <geom material="M_hinge_blue" pos="-0.185 -.015 0" size="0.193 0.03 0.2" type="box"/>
                        <geom material="M_hinge_metal" pos="-0.302 -0.128 0" size="0.022 0.16" type="cylinder"/>
                        <geom material="M_hinge_metal" pos="-0.302 -0.061 -0.114" euler="1.57 0 0" size="0.019 0.053 0.02" type="cylinder"/>
                        <geom material="M_hinge_metal" pos="-0.302 -0.061 0.114" euler="1.57 0 0" size="0.019 0.053 0.02" type="cylinder"/>
                        <geom class="hinge_collision" pos="-0.302 -0.128 0" size="0.022 0.16" type="cylinder" mass=".1"/>
                        <geom class="hinge_collision" pos="-0.302 -0.061 -0.114" euler="1.57 0 0" size="0.019 0.053 0.02" type="cylinder" mass=".02"/>
                        <geom class="hinge_collision" pos="-0.302 -0.061 0.114" euler="1.57 0 0" size="0.019 0.053 0.02" type="cylinder" mass=".02"/>
                        <geom class="hinge_collision" pos="-0.185 -.015 0" size="0.193 0.03 0.2" type="box" mass=".2"/>
                        <site type="sphere" name="hinge_site2" pos="-0.302 -0.128 0" size=".01" group="3" rgba="0 1 0 1"/>
                    </body>
                </body>
            </body>
            <body name="microwave" pos="-0.750 -0.025 1.6" euler="0 0 0.3">
                <!-- <include file="item_assets/microwave_chain.xml"/> -->
                <body name="microroot" childclass="microwave">
                    <geom mesh="micro" type="mesh"/>
                    <geom material="micro_metal" mesh="microbutton" type="mesh"/>
                    <geom material="micro_metal" mesh="microfeet" type="mesh"/>
                    <geom class="micro_collision" pos="-0.316 0.023 0.187" size="0.029 0.199 0.187" type="box" mass=".5"/>
                    <geom class="micro_collision" pos="0.236 0.023 0.187" size="0.109 0.199 0.187" type="box" mass=".5"/>
                    <geom class="micro_collision" pos="-0.081 0.191 0.187" size="0.207 0.03 0.187" type="box" mass=".5"/>
                    <geom class="micro_collision" pos="-0.08 -0.007 0.355" size="0.207 0.169 0.019" type="box" mass=".5"/>
                    <geom class="micro_collision" pos="-0.08 -0.008 0.024" size="0.207 0.168 0.024" type="box" mass=".5"/>
                    <geom class="micro_collision" pos="0.26 -0.197 0.187" size="0.085 0.024 0.187" type="box" mass=".5"/>
                    <body name="microdoorroot" pos="-0.345 -0.176 0.192">
                        <joint axis="0 0 1" limited="true" name="microwave" range="-2.094 0" type="hinge"/>
                        <geom mesh="microdoor" pos="0.345 0.176 -0.192" type="mesh"/>
                        <geom material="micro_window" mesh="microwindow" pos="0.345 0.176 -0.192" type="mesh"/>
                        <geom material="micro_metal" pos="0.475 -0.108 0" size="0.02 0.13" type="capsule"/>
                        <geom material="micro_metal" euler="1.57 0 0" pos="0.475 -0.075 .13" size="0.02 0.03" type="capsule"/>
                        <geom material="micro_metal" euler="1.57 0 0" pos="0.475 -0.075 -.13" size="0.02 0.03" type="capsule"/>
                        <geom class="micro_collision" pos="0.475 -0.108 0" size="0.02 0.13" type="capsule" mass="0.020"/>
                        <geom class="micro_collision" euler="1.57 0 0" pos="0.475 -0.075 .13" size="0.02 0.03" type="capsule" mass="0.020"/>
                        <geom class="micro_collision" euler="1.57 0 0" pos="0.475 -0.075 -.13" size="0.02 0.03" type="capsule" mass="0.020"/>
                        <geom class="micro_collision" pos="0.259 -0.026 0" size="0.259 0.024 0.185" type="box" mass="0.20"/>
                        <site type="sphere" name="microhandle_site" pos="0.475 -0.108 0" size=".01" group="3" rgba="1 1 0 1"/>
                    </body>
                </body>
            </body>
        </body>
        <body name="kettle" pos="-0.269 0.35 1.626">
            <!-- <freejoint name="kettle"/> -->
            <!-- <include file="item_assets/kettle_chain.xml"/> -->
            <body name="kettleroot" childclass="kettle">
                <geom mesh="kettle" type="mesh"/>
                <geom material="kettle_wood" euler="0 1.57 0" pos="0 0 0.259" size="0.032 0.1" type="capsule"/>
                <geom material="kettle_wood" euler="0 1.57 0" pos="0 0 0.13" size="0.011" type="sphere"/>
                <geom euler="0 1.57 0" pos="0 0 0.259" size="0.02 0.115" type="capsule"/>
                <geom pos="0.092 0 0.186" size="0.02 0.07" type="capsule"/>
                <geom pos="-0.092 0 0.185" size="0.02 0.07" type="capsule"/>
                <geom material="kettle_wood" pos="-0.092 0 0.22" size="0.022 0.015" type="capsule"/>
                <geom material="kettle_wood" pos="0.092 0 0.22" size="0.022 0.015" type="capsule"/>
                <geom class="kettle_collision" euler="0 1.57 0" pos="0 0 0.259" size="0.032 0.1" type="capsule" mass='.02'/>
                <geom class="kettle_collision" pos="0.092 0 0.18" size="0.023 0.06" type="capsule" mass='.02'/>
                <geom class="kettle_collision" pos="-0.092 0 0.18" size="0.023 0.06" type="capsule" mass='.02'/>
                <geom class="kettle_collision" euler="0 2.25 0" pos="-0.126 0 0.07" size="0.031 0.05" type="cylinder" mass='.02'/>
                <geom class="kettle_collision" pos="0 0 0.058" size="0.122 0.122 0.058" type="box" mass='.8'/>
                <site type="sphere" name="kettle_site" pos="0 0 0.259" size=".01" group="3" rgba="1 0 0 1"/>
            </body>
        </body>
    </worldbody>
    <!-- <include file="../franka_assets/actuator.xml"/> -->

    <keyframe>
        <key name="home" ctrl="0.16 -1.76 1.84 -2.51 0.36 0.79 1.55 255"/>
    </keyframe>

</mujoco>
